Workbook

Sheet Programme de vols
B1: PROGRAMME DE VOLS MENSUEL - ANNEE D'EXPLOITATION AVRIL 2027 / MARS 2028
B2: Feuille unique de programmation : les deux filtres ci-dessous (Mois et Route) pilotent la grille, le recapitulatif ne suit que le filtre Mois. La saisie se fait dans 12 tableaux identiques, un par mois : chaque route y occupe 3 lignes, une par type avion (77W / 778 / A320), et il suffit de COCHER les jours d'operation. La feuille "Analyse capacite" traduit ce programme en sieges offerts.
N3: REPERES CALCULES | W3: Mois (filtre) | X3: 1er jour | Y3: Types avion | Z3: Routes
B4: FILTRE MOIS | C4: avril 2027 | E4: <-- liste deroulante : selectionne le tableau de saisie lu (la structure ne change pas) | N4: 1er jour du mois | O4: =INDEX($X$4:$X$15,MATCH($C$4,$W$4:$W$15,0)) -> 46478 | W4: avril 2027 | X4: =DATE(2027,4,1) -> 46478 | Y4: 77W | Z4: CDGRUN
B5: FILTRE ROUTE | C5: NOSRUN | E5: <-- liste deroulante : pilote la grille uniquement | N5: Dernier jour du mois | O5: =EOMONTH($O$4,0) -> 46507 | W5: mai 2027 | X5: =DATE(2027,5,1) -> 46508 | Y5: 778 | Z5: CDGDZA
B6: GRILLE MENSUELLE - type avion opere par semaine et par jour (filtres Mois + Route) | N6: Lundi semaine 1 | O6: =$O$4-WEEKDAY($O$4,3) -> 46475 | W6: juin 2027 | X6: =DATE(2027,6,1) -> 46539 | Y6: A320 | Z6: BKKRUN
B7: Semaine | C7: J1 - Lundi | D7: J2 - Mardi | E7: J3 - Mercredi | F7: J4 - Jeudi | G7: J5 - Vendredi | H7: J6 - Samedi | I7: J7 - Dimanche | N7: Tableau de saisie lu | O7: =MATCH($C$4,$W$4:$W$15,0) -> 1 | W7: juillet 2027 | X7: =DATE(2027,7,1) -> 46569 | Z7: DZARUN
B8: Semaine 1 | C8: =IF(C9="","",TRIM($O$17&IF(SUMIFS($E$521:$E$560,$C$521:$C$560,$C$5,$B$521:$B$560,C9)=0,""," (+"&IF(COUNTIFS($C$521:$C$560,$C$5,$B$521:$B$560,C9)=1,IF(SUMIFS($E$521:$E$560,$C$521:$C$560,$C$5,$B$521:$B$560,C9)=1,IFERROR(INDEX($D$521:$D$560,MATCH(C9&"|"&$C$5,$H$521:$H$560,0)),""),SUMIFS($E$521:$E$560,$C$521:$C$560,$C$5,$B$521:$B$560,C9)&"x"&IFERROR(INDEX($D$521:$D$560,MATCH(C9&"|"&$C$5,$H$521:$H$560,0)),"")),SUMIFS($E$521:$E$560,$C$521:$C$560,$C$5,$B$521:$B$560,C9)&" vols")&")"))) | D8: =IF(D9="","",TRIM($P$17&IF(SUMIFS($E$521:$E$560,$C$521:$C$560,$C$5,$B$521:$B$560,D9)=0,""," (+"&IF(COUNTIFS($C$521:$C$560,$C$5,$B$521:$B$560,D9)=1,IF(SUMIFS($E$521:$E$560,$C$521:$C$560,$C$5,$B$521:$B$560,D9)=1,IFERROR(INDEX($D$521:$D$560,MATCH(D9&"|"&$C$5,$H$521:$H$560,0)),""),SUMIFS($E$521:$E$560,$C$521:$C$560,$C$5,$B$521:$B$560,D9)&"x"&IFERROR(INDEX($D$521:$D$560,MATCH(D9&"|"&$C$5,$H$521:$H$560,0)),"")),SUMIFS($E$521:$E$560,$C$521:$C$560,$C$5,$B$521:$B$560,D9)&" vols")&")"))) | E8: =IF(E9="","",TRIM($Q$17&IF(SUMIFS($E$521:$E$560,$C$521:$C$560,$C$5,$B$521:$B$560,E9)=0,""," (+"&IF(COUNTIFS($C$521:$C$560,$C$5,$B$521:$B$560,E9)=1,IF(SUMIFS($E$521:$E$560,$C$521:$C$560,$C$5,$B$521:$B$560,E9)=1,IFERROR(INDEX($D$521:$D$560,MATCH(E9&"|"&$C$5,$H$521:$H$560,0)),""),SUMIFS($E$521:$E$560,$C$521:$C$560,$C$5,$B$521:$B$560,E9)&"x"&IFERROR(INDEX($D$521:$D$560,MATCH(E9&"|"&$C$5,$H$521:$H$560,0)),"")),SUMIFS($E$521:$E$560,$C$521:$C$560,$C$5,$B$521:$B$560,E9)&" vols")&")"))) | F8: =IF(F9="","",TRIM($R$17&IF(SUMIFS($E$521:$E$560,$C$521:$C$560,$C$5,$B$521:$B$560,F9)=0,""," (+"&IF(COUNTIFS($C$521:$C$560,$C$5,$B$521:$B$560,F9)=1,IF(SUMIFS($E$521:$E$560,$C$521:$C$560,$C$5,$B$521:$B$560,F9)=1,IFERROR(INDEX($D$521:$D$560,MATCH(F9&"|"&$C$5,$H$521:$H$560,0)),""),SUMIFS($E$521:$E$560,$C$521:$C$560,$C$5,$B$521:$B$560,F9)&"x"&IFERROR(INDEX($D$521:$D$560,MATCH(F9&"|"&$C$5,$H$521:$H$560,0)),"")),SUMIFS($E$521:$E$560,$C$521:$C$560,$C$5,$B$521:$B$560,F9)&" vols")&")"))) -> A320 | G8: =IF(G9="","",TRIM($S$17&IF(SUMIFS($E$521:$E$560,$C$521:$C$560,$C$5,$B$521:$B$560,G9)=0,""," (+"&IF(COUNTIFS($C$521:$C$560,$C$5,$B$521:$B$560,G9)=1,IF(SUMIFS($E$521:$E$560,$C$521:$C$560,$C$5,$B$521:$B$560,G9)=1,IFERROR(INDEX($D$521:$D$560,MATCH(G9&"|"&$C$5,$H$521:$H$560,0)),""),SUMIFS($E$521:$E$560,$C$521:$C$560,$C$5,$B$521:$B$560,G9)&"x"&IFERROR(INDEX($D$521:$D$560,MATCH(G9&"|"&$C$5,$H$521:$H$560,0)),"")),SUMIFS($E$521:$E$560,$C$521:$C$560,$C$5,$B$521:$B$560,G9)&" vols")&")"))) | H8: =IF(H9="","",TRIM($T$17&IF(SUMIFS($E$521:$E$560,$C$521:$C$560,$C$5,$B$521:$B$560,H9)=0,""," (+"&IF(COUNTIFS($C$521:$C$560,$C$5,$B$521:$B$560,H9)=1,IF(SUMIFS($E$521:$E$560,$C$521:$C$560,$C$5,$B$521:$B$560,H9)=1,IFERROR(INDEX($D$521:$D$560,MATCH(H9&"|"&$C$5,$H$521:$H$560,0)),""),SUMIFS($E$521:$E$560,$C$521:$C$560,$C$5,$B$521:$B$560,H9)&"x"&IFERROR(INDEX($D$521:$D$560,MATCH(H9&"|"&$C$5,$H$521:$H$560,0)),"")),SUMIFS($E$521:$E$560,$C$521:$C$560,$C$5,$B$521:$B$560,H9)&" vols")&")"))) -> A320 | I8: =IF(I9="","",TRIM($U$17&IF(SUMIFS($E$521:$E$560,$C$521:$C$560,$C$5,$B$521:$B$560,I9)=0,""," (+"&IF(COUNTIFS($C$521:$C$560,$C$5,$B$521:$B$560,I9)=1,IF(SUMIFS($E$521:$E$560,$C$521:$C$560,$C$5,$B$521:$B$560,I9)=1,IFERROR(INDEX($D$521:$D$560,MATCH(I9&"|"&$C$5,$H$521:$H$560,0)),""),SUMIFS($E$521:$E$560,$C$521:$C$560,$C$5,$B$521:$B$560,I9)&"x"&IFERROR(INDEX($D$521:$D$560,MATCH(I9&"|"&$C$5,$H$521:$H$560,0)),"")),SUMIFS($E$521:$E$560,$C$521:$C$560,$C$5,$B$521:$B$560,I9)&" vols")&")"))) | N8: Type(s) avion | O8: =IFERROR(INDEX($C$25:$C$36,MATCH($C$5,$B$25:$B$36,0)),"") -> A320(3) | W8: aout 2027 | X8: =DATE(2027,8,1) -> 46600 | Z8: MRURUN
B9: =IF(COUNT(C9:I9)=0,"","du "&TEXT(MIN(C9:I9),"DD/MM")&" au "&TEXT(MAX(C9:I9),"DD/MM")) -> du 01/04 au 04/04 | C9: =IF(OR($O$6+0<$O$4,$O$6+0>$O$5),"",$O$6+0) | D9: =IF(OR($O$6+1<$O$4,$O$6+1>$O$5),"",$O$6+1) | E9: =IF(OR($O$6+2<$O$4,$O$6+2>$O$5),"",$O$6+2) | F9: =IF(OR($O$6+3<$O$4,$O$6+3>$O$5),"",$O$6+3) -> 46478 | G9: =IF(OR($O$6+4<$O$4,$O$6+4>$O$5),"",$O$6+4) -> 46479 | H9: =IF(OR($O$6+5<$O$4,$O$6+5>$O$5),"",$O$6+5) -> 46480 | I9: =IF(OR($O$6+6<$O$4,$O$6+6>$O$5),"",$O$6+6) -> 46481 | N9: Rotations / semaine | O9: =IFERROR(INDEX($E$25:$E$36,MATCH($C$5,$B$25:$B$36,0)),"") -> 3 | W9: septembre 2027 | X9: =DATE(2027,9,1) -> 46631 | Z9: NOSRUN
B10: Semaine 2 | C10: =IF(C11="","",TRIM($O$17&IF(SUMIFS($E$521:$E$560,$C$521:$C$560,$C$5,$B$521:$B$560,C11)=0,""," (+"&IF(COUNTIFS($C$521:$C$560,$C$5,$B$521:$B$560,C11)=1,IF(SUMIFS($E$521:$E$560,$C$521:$C$560,$C$5,$B$521:$B$560,C11)=1,IFERROR(INDEX($D$521:$D$560,MATCH(C11&"|"&$C$5,$H$521:$H$560,0)),""),SUMIFS($E$521:$E$560,$C$521:$C$560,$C$5,$B$521:$B$560,C11)&"x"&IFERROR(INDEX($D$521:$D$560,MATCH(C11&"|"&$C$5,$H$521:$H$560,0)),"")),SUMIFS($E$521:$E$560,$C$521:$C$560,$C$5,$B$521:$B$560,C11)&" vols")&")"))) -> A320 | D10: =IF(D11="","",TRIM($P$17&IF(SUMIFS($E$521:$E$560,$C$521:$C$560,$C$5,$B$521:$B$560,D11)=0,""," (+"&IF(COUNTIFS($C$521:$C$560,$C$5,$B$521:$B$560,D11)=1,IF(SUMIFS($E$521:$E$560,$C$521:$C$560,$C$5,$B$521:$B$560,D11)=1,IFERROR(INDEX($D$521:$D$560,MATCH(D11&"|"&$C$5,$H$521:$H$560,0)),""),SUMIFS($E$521:$E$560,$C$521:$C$560,$C$5,$B$521:$B$560,D11)&"x"&IFERROR(INDEX($D$521:$D$560,MATCH(D11&"|"&$C$5,$H$521:$H$560,0)),"")),SUMIFS($E$521:$E$560,$C$521:$C$560,$C$5,$B$521:$B$560,D11)&" vols")&")"))) | E10: =IF(E11="","",TRIM($Q$17&IF(SUMIFS($E$521:$E$560,$C$521:$C$560,$C$5,$B$521:$B$560,E11)=0,""," (+"&IF(COUNTIFS($C$521:$C$560,$C$5,$B$521:$B$560,E11)=1,IF(SUMIFS($E$521:$E$560,$C$521:$C$560,$C$5,$B$521:$B$560,E11)=1,IFERROR(INDEX($D$521:$D$560,MATCH(E11&"|"&$C$5,$H$521:$H$560,0)),""),SUMIFS($E$521:$E$560,$C$521:$C$560,$C$5,$B$521:$B$560,E11)&"x"&IFERROR(INDEX($D$521:$D$560,MATCH(E11&"|"&$C$5,$H$521:$H$560,0)),"")),SUMIFS($E$521:$E$560,$C$521:$C$560,$C$5,$B$521:$B$560,E11)&" vols")&")"))) -> (+A320) | F10: =IF(F11="","",TRIM($R$17&IF(SUMIFS($E$521:$E$560,$C$521:$C$560,$C$5,$B$521:$B$560,F11)=0,""," (+"&IF(COUNTIFS($C$521:$C$560,$C$5,$B$521:$B$560,F11)=1,IF(SUMIFS($E$521:$E$560,$C$521:$C$560,$C$5,$B$521:$B$560,F11)=1,IFERROR(INDEX($D$521:$D$560,MATCH(F11&"|"&$C$5,$H$521:$H$560,0)),""),SUMIFS($E$521:$E$560,$C$521:$C$560,$C$5,$B$521:$B$560,F11)&"x"&IFERROR(INDEX($D$521:$D$560,MATCH(F11&"|"&$C$5,$H$521:$H$560,0)),"")),SUMIFS($E$521:$E$560,$C$521:$C$560,$C$5,$B$521:$B$560,F11)&" vols")&")"))) -> A320 | G10: =IF(G11="","",TRIM($S$17&IF(SUMIFS($E$521:$E$560,$C$521:$C$560,$C$5,$B$521:$B$560,G11)=0,""," (+"&IF(COUNTIFS($C$521:$C$560,$C$5,$B$521:$B$560,G11)=1,IF(SUMIFS($E$521:$E$560,$C$521:$C$560,$C$5,$B$521:$B$560,G11)=1,IFERROR(INDEX($D$521:$D$560,MATCH(G11&"|"&$C$5,$H$521:$H$560,0)),""),SUMIFS($E$521:$E$560,$C$521:$C$560,$C$5,$B$521:$B$560,G11)&"x"&IFERROR(INDEX($D$521:$D$560,MATCH(G11&"|"&$C$5,$H$521:$H$560,0)),"")),SUMIFS($E$521:$E$560,$C$521:$C$560,$C$5,$B$521:$B$560,G11)&" vols")&")"))) | H10: =IF(H11="","",TRIM($T$17&IF(SUMIFS($E$521:$E$560,$C$521:$C$560,$C$5,$B$521:$B$560,H11)=0,""," (+"&IF(COUNTIFS($C$521:$C$560,$C$5,$B$521:$B$560,H11)=1,IF(SUMIFS($E$521:$E$560,$C$521:$C$560,$C$5,$B$521:$B$560,H11)=1,IFERROR(INDEX($D$521:$D$560,MATCH(H11&"|"&$C$5,$H$521:$H$560,0)),""),SUMIFS($E$521:$E$560,$C$521:$C$560,$C$5,$B$521:$B$560,H11)&"x"&IFERROR(INDEX($D$521:$D$560,MATCH(H11&"|"&$C$5,$H$521:$H$560,0)),"")),SUMIFS($E$521:$E$560,$C$521:$C$560,$C$5,$B$521:$B$560,H11)&" vols")&")"))) -> A320 (+A320) | I10: =IF(I11="","",TRIM($U$17&IF(SUMIFS($E$521:$E$560,$C$521:$C$560,$C$5,$B$521:$B$560,I11)=0,""," (+"&IF(COUNTIFS($C$521:$C$560,$C$5,$B$521:$B$560,I11)=1,IF(SUMIFS($E$521:$E$560,$C$521:$C$560,$C$5,$B$521:$B$560,I11)=1,IFERROR(INDEX($D$521:$D$560,MATCH(I11&"|"&$C$5,$H$521:$H$560,0)),""),SUMIFS($E$521:$E$560,$C$521:$C$560,$C$5,$B$521:$B$560,I11)&"x"&IFERROR(INDEX($D$521:$D$560,MATCH(I11&"|"&$C$5,$H$521:$H$560,0)),"")),SUMIFS($E$521:$E$560,$C$521:$C$560,$C$5,$B$521:$B$560,I11)&" vols")&")"))) | N10: Total rotations du mois | O10: =IFERROR(INDEX($G$25:$G$36,MATCH($C$5,$B$25:$B$36,0)),"") -> 15 | W10: octobre 2027 | X10: =DATE(2027,10,1) -> 46661 | Z10: RUNTNR
B11: =IF(COUNT(C11:I11)=0,"","du "&TEXT(MIN(C11:I11),"DD/MM")&" au "&TEXT(MAX(C11:I11),"DD/MM")) -> du 05/04 au 11/04 | C11: =IF(OR($O$6+7<$O$4,$O$6+7>$O$5),"",$O$6+7) -> 46482 | D11: =IF(OR($O$6+8<$O$4,$O$6+8>$O$5),"",$O$6+8) -> 46483 | E11: =IF(OR($O$6+9<$O$4,$O$6+9>$O$5),"",$O$6+9) -> 46484 | F11: =IF(OR($O$6+10<$O$4,$O$6+10>$O$5),"",$O$6+10) -> 46485 | G11: =IF(OR($O$6+11<$O$4,$O$6+11>$O$5),"",$O$6+11) -> 46486 | H11: =IF(OR($O$6+12<$O$4,$O$6+12>$O$5),"",$O$6+12) -> 46487 | I11: =IF(OR($O$6+13<$O$4,$O$6+13>$O$5),"",$O$6+13) -> 46488 | N11: dont 77W | O11: =IFERROR(INDEX($J$25:$J$36,MATCH($C$5,$B$25:$B$36,0)),"") -> 0 | W11: novembre 2027 | X11: =DATE(2027,11,1) -> 46692 | Z11: JNBRUN
B12: Semaine 3 | C12: =IF(C13="","",TRIM($O$17&IF(SUMIFS($E$521:$E$560,$C$521:$C$560,$C$5,$B$521:$B$560,C13)=0,""," (+"&IF(COUNTIFS($C$521:$C$560,$C$5,$B$521:$B$560,C13)=1,IF(SUMIFS($E$521:$E$560,$C$521:$C$560,$C$5,$B$521:$B$560,C13)=1,IFERROR(INDEX($D$521:$D$560,MATCH(C13&"|"&$C$5,$H$521:$H$560,0)),""),SUMIFS($E$521:$E$560,$C$521:$C$560,$C$5,$B$521:$B$560,C13)&"x"&IFERROR(INDEX($D$521:$D$560,MATCH(C13&"|"&$C$5,$H$521:$H$560,0)),"")),SUMIFS($E$521:$E$560,$C$521:$C$560,$C$5,$B$521:$B$560,C13)&" vols")&")"))) -> A320 | D12: =IF(D13="","",TRIM($P$17&IF(SUMIFS($E$521:$E$560,$C$521:$C$560,$C$5,$B$521:$B$560,D13)=0,""," (+"&IF(COUNTIFS($C$521:$C$560,$C$5,$B$521:$B$560,D13)=1,IF(SUMIFS($E$521:$E$560,$C$521:$C$560,$C$5,$B$521:$B$560,D13)=1,IFERROR(INDEX($D$521:$D$560,MATCH(D13&"|"&$C$5,$H$521:$H$560,0)),""),SUMIFS($E$521:$E$560,$C$521:$C$560,$C$5,$B$521:$B$560,D13)&"x"&IFERROR(INDEX($D$521:$D$560,MATCH(D13&"|"&$C$5,$H$521:$H$560,0)),"")),SUMIFS($E$521:$E$560,$C$521:$C$560,$C$5,$B$521:$B$560,D13)&" vols")&")"))) | E12: =IF(E13="","",TRIM($Q$17&IF(SUMIFS($E$521:$E$560,$C$521:$C$560,$C$5,$B$521:$B$560,E13)=0,""," (+"&IF(COUNTIFS($C$521:$C$560,$C$5,$B$521:$B$560,E13)=1,IF(SUMIFS($E$521:$E$560,$C$521:$C$560,$C$5,$B$521:$B$560,E13)=1,IFERROR(INDEX($D$521:$D$560,MATCH(E13&"|"&$C$5,$H$521:$H$560,0)),""),SUMIFS($E$521:$E$560,$C$521:$C$560,$C$5,$B$521:$B$560,E13)&"x"&IFERROR(INDEX($D$521:$D$560,MATCH(E13&"|"&$C$5,$H$521:$H$560,0)),"")),SUMIFS($E$521:$E$560,$C$521:$C$560,$C$5,$B$521:$B$560,E13)&" vols")&")"))) | F12: =IF(F13="","",TRIM($R$17&IF(SUMIFS($E$521:$E$560,$C$521:$C$560,$C$5,$B$521:$B$560,F13)=0,""," (+"&IF(COUNTIFS($C$521:$C$560,$C$5,$B$521:$B$560,F13)=1,IF(SUMIFS($E$521:$E$560,$C$521:$C$560,$C$5,$B$521:$B$560,F13)=1,IFERROR(INDEX($D$521:$D$560,MATCH(F13&"|"&$C$5,$H$521:$H$560,0)),""),SUMIFS($E$521:$E$560,$C$521:$C$560,$C$5,$B$521:$B$560,F13)&"x"&IFERROR(INDEX($D$521:$D$560,MATCH(F13&"|"&$C$5,$H$521:$H$560,0)),"")),SUMIFS($E$521:$E$560,$C$521:$C$560,$C$5,$B$521:$B$560,F13)&" vols")&")"))) -> A320 | G12: =IF(G13="","",TRIM($S$17&IF(SUMIFS($E$521:$E$560,$C$521:$C$560,$C$5,$B$521:$B$560,G13)=0,""," (+"&IF(COUNTIFS($C$521:$C$560,$C$5,$B$521:$B$560,G13)=1,IF(SUMIFS($E$521:$E$560,$C$521:$C$560,$C$5,$B$521:$B$560,G13)=1,IFERROR(INDEX($D$521:$D$560,MATCH(G13&"|"&$C$5,$H$521:$H$560,0)),""),SUMIFS($E$521:$E$560,$C$521:$C$560,$C$5,$B$521:$B$560,G13)&"x"&IFERROR(INDEX($D$521:$D$560,MATCH(G13&"|"&$C$5,$H$521:$H$560,0)),"")),SUMIFS($E$521:$E$560,$C$521:$C$560,$C$5,$B$521:$B$560,G13)&" vols")&")"))) | H12: =IF(H13="","",TRIM($T$17&IF(SUMIFS($E$521:$E$560,$C$521:$C$560,$C$5,$B$521:$B$560,H13)=0,""," (+"&IF(COUNTIFS($C$521:$C$560,$C$5,$B$521:$B$560,H13)=1,IF(SUMIFS($E$521:$E$560,$C$521:$C$560,$C$5,$B$521:$B$560,H13)=1,IFERROR(INDEX($D$521:$D$560,MATCH(H13&"|"&$C$5,$H$521:$H$560,0)),""),SUMIFS($E$521:$E$560,$C$521:$C$560,$C$5,$B$521:$B$560,H13)&"x"&IFERROR(INDEX($D$521:$D$560,MATCH(H13&"|"&$C$5,$H$521:$H$560,0)),"")),SUMIFS($E$521:$E$560,$C$521:$C$560,$C$5,$B$521:$B$560,H13)&" vols")&")"))) -> A320 | I12: =IF(I13="","",TRIM($U$17&IF(SUMIFS($E$521:$E$560,$C$521:$C$560,$C$5,$B$521:$B$560,I13)=0,""," (+"&IF(COUNTIFS($C$521:$C$560,$C$5,$B$521:$B$560,I13)=1,IF(SUMIFS($E$521:$E$560,$C$521:$C$560,$C$5,$B$521:$B$560,I13)=1,IFERROR(INDEX($D$521:$D$560,MATCH(I13&"|"&$C$5,$H$521:$H$560,0)),""),SUMIFS($E$521:$E$560,$C$521:$C$560,$C$5,$B$521:$B$560,I13)&"x"&IFERROR(INDEX($D$521:$D$560,MATCH(I13&"|"&$C$5,$H$521:$H$560,0)),"")),SUMIFS($E$521:$E$560,$C$521:$C$560,$C$5,$B$521:$B$560,I13)&" vols")&")"))) | N12: dont 778 | O12: =IFERROR(INDEX($K$25:$K$36,MATCH($C$5,$B$25:$B$36,0)),"") -> 0 | W12: decembre 2027 | X12: =DATE(2027,12,1) -> 46722 | Z12: CPTRUN
B13: =IF(COUNT(C13:I13)=0,"","du "&TEXT(MIN(C13:I13),"DD/MM")&" au "&TEXT(MAX(C13:I13),"DD/MM")) -> du 12/04 au 18/04 | C13: =IF(OR($O$6+14<$O$4,$O$6+14>$O$5),"",$O$6+14) -> 46489 | D13: =IF(OR($O$6+15<$O$4,$O$6+15>$O$5),"",$O$6+15) -> 46490 | E13: =IF(OR($O$6+16<$O$4,$O$6+16>$O$5),"",$O$6+16) -> 46491 | F13: =IF(OR($O$6+17<$O$4,$O$6+17>$O$5),"",$O$6+17) -> 46492 | G13: =IF(OR($O$6+18<$O$4,$O$6+18>$O$5),"",$O$6+18) -> 46493 | H13: =IF(OR($O$6+19<$O$4,$O$6+19>$O$5),"",$O$6+19) -> 46494 | I13: =IF(OR($O$6+20<$O$4,$O$6+20>$O$5),"",$O$6+20) -> 46495 | N13: dont A320 | O13: =IFERROR(INDEX($L$25:$L$36,MATCH($C$5,$B$25:$B$36,0)),"") -> 15 | W13: janvier 2028 | X13: =DATE(2028,1,1) -> 46753 | Z13: DIERUN
B14: Semaine 4 | C14: =IF(C15="","",TRIM($O$17&IF(SUMIFS($E$521:$E$560,$C$521:$C$560,$C$5,$B$521:$B$560,C15)=0,""," (+"&IF(COUNTIFS($C$521:$C$560,$C$5,$B$521:$B$560,C15)=1,IF(SUMIFS($E$521:$E$560,$C$521:$C$560,$C$5,$B$521:$B$560,C15)=1,IFERROR(INDEX($D$521:$D$560,MATCH(C15&"|"&$C$5,$H$521:$H$560,0)),""),SUMIFS($E$521:$E$560,$C$521:$C$560,$C$5,$B$521:$B$560,C15)&"x"&IFERROR(INDEX($D$521:$D$560,MATCH(C15&"|"&$C$5,$H$521:$H$560,0)),"")),SUMIFS($E$521:$E$560,$C$521:$C$560,$C$5,$B$521:$B$560,C15)&" vols")&")"))) -> A320 | D14: =IF(D15="","",TRIM($P$17&IF(SUMIFS($E$521:$E$560,$C$521:$C$560,$C$5,$B$521:$B$560,D15)=0,""," (+"&IF(COUNTIFS($C$521:$C$560,$C$5,$B$521:$B$560,D15)=1,IF(SUMIFS($E$521:$E$560,$C$521:$C$560,$C$5,$B$521:$B$560,D15)=1,IFERROR(INDEX($D$521:$D$560,MATCH(D15&"|"&$C$5,$H$521:$H$560,0)),""),SUMIFS($E$521:$E$560,$C$521:$C$560,$C$5,$B$521:$B$560,D15)&"x"&IFERROR(INDEX($D$521:$D$560,MATCH(D15&"|"&$C$5,$H$521:$H$560,0)),"")),SUMIFS($E$521:$E$560,$C$521:$C$560,$C$5,$B$521:$B$560,D15)&" vols")&")"))) | E14: =IF(E15="","",TRIM($Q$17&IF(SUMIFS($E$521:$E$560,$C$521:$C$560,$C$5,$B$521:$B$560,E15)=0,""," (+"&IF(COUNTIFS($C$521:$C$560,$C$5,$B$521:$B$560,E15)=1,IF(SUMIFS($E$521:$E$560,$C$521:$C$560,$C$5,$B$521:$B$560,E15)=1,IFERROR(INDEX($D$521:$D$560,MATCH(E15&"|"&$C$5,$H$521:$H$560,0)),""),SUMIFS($E$521:$E$560,$C$521:$C$560,$C$5,$B$521:$B$560,E15)&"x"&IFERROR(INDEX($D$521:$D$560,MATCH(E15&"|"&$C$5,$H$521:$H$560,0)),"")),SUMIFS($E$521:$E$560,$C$521:$C$560,$C$5,$B$521:$B$560,E15)&" vols")&")"))) | F14: =IF(F15="","",TRIM($R$17&IF(SUMIFS($E$521:$E$560,$C$521:$C$560,$C$5,$B$521:$B$560,F15)=0,""," (+"&IF(COUNTIFS($C$521:$C$560,$C$5,$B$521:$B$560,F15)=1,IF(SUMIFS($E$521:$E$560,$C$521:$C$560,$C$5,$B$521:$B$560,F15)=1,IFERROR(INDEX($D$521:$D$560,MATCH(F15&"|"&$C$5,$H$521:$H$560,0)),""),SUMIFS($E$521:$E$560,$C$521:$C$560,$C$5,$B$521:$B$560,F15)&"x"&IFERROR(INDEX($D$521:$D$560,MATCH(F15&"|"&$C$5,$H$521:$H$560,0)),"")),SUMIFS($E$521:$E$560,$C$521:$C$560,$C$5,$B$521:$B$560,F15)&" vols")&")"))) -> A320 | G14: =IF(G15="","",TRIM($S$17&IF(SUMIFS($E$521:$E$560,$C$521:$C$560,$C$5,$B$521:$B$560,G15)=0,""," (+"&IF(COUNTIFS($C$521:$C$560,$C$5,$B$521:$B$560,G15)=1,IF(SUMIFS($E$521:$E$560,$C$521:$C$560,$C$5,$B$521:$B$560,G15)=1,IFERROR(INDEX($D$521:$D$560,MATCH(G15&"|"&$C$5,$H$521:$H$560,0)),""),SUMIFS($E$521:$E$560,$C$521:$C$560,$C$5,$B$521:$B$560,G15)&"x"&IFERROR(INDEX($D$521:$D$560,MATCH(G15&"|"&$C$5,$H$521:$H$560,0)),"")),SUMIFS($E$521:$E$560,$C$521:$C$560,$C$5,$B$521:$B$560,G15)&" vols")&")"))) | H14: =IF(H15="","",TRIM($T$17&IF(SUMIFS($E$521:$E$560,$C$521:$C$560,$C$5,$B$521:$B$560,H15)=0,""," (+"&IF(COUNTIFS($C$521:$C$560,$C$5,$B$521:$B$560,H15)=1,IF(SUMIFS($E$521:$E$560,$C$521:$C$560,$C$5,$B$521:$B$560,H15)=1,IFERROR(INDEX($D$521:$D$560,MATCH(H15&"|"&$C$5,$H$521:$H$560,0)),""),SUMIFS($E$521:$E$560,$C$521:$C$560,$C$5,$B$521:$B$560,H15)&"x"&IFERROR(INDEX($D$521:$D$560,MATCH(H15&"|"&$C$5,$H$521:$H$560,0)),"")),SUMIFS($E$521:$E$560,$C$521:$C$560,$C$5,$B$521:$B$560,H15)&" vols")&")"))) -> A320 | I14: =IF(I15="","",TRIM($U$17&IF(SUMIFS($E$521:$E$560,$C$521:$C$560,$C$5,$B$521:$B$560,I15)=0,""," (+"&IF(COUNTIFS($C$521:$C$560,$C$5,$B$521:$B$560,I15)=1,IF(SUMIFS($E$521:$E$560,$C$521:$C$560,$C$5,$B$521:$B$560,I15)=1,IFERROR(INDEX($D$521:$D$560,MATCH(I15&"|"&$C$5,$H$521:$H$560,0)),""),SUMIFS($E$521:$E$560,$C$521:$C$560,$C$5,$B$521:$B$560,I15)&"x"&IFERROR(INDEX($D$521:$D$560,MATCH(I15&"|"&$C$5,$H$521:$H$560,0)),"")),SUMIFS($E$521:$E$560,$C$521:$C$560,$C$5,$B$521:$B$560,I15)&" vols")&")"))) | W14: fevrier 2028 | X14: =DATE(2028,2,1) -> 46784 | Z14: RRGRUN
B15: =IF(COUNT(C15:I15)=0,"","du "&TEXT(MIN(C15:I15),"DD/MM")&" au "&TEXT(MAX(C15:I15),"DD/MM")) -> du 19/04 au 25/04 | C15: =IF(OR($O$6+21<$O$4,$O$6+21>$O$5),"",$O$6+21) -> 46496 | D15: =IF(OR($O$6+22<$O$4,$O$6+22>$O$5),"",$O$6+22) -> 46497 | E15: =IF(OR($O$6+23<$O$4,$O$6+23>$O$5),"",$O$6+23) -> 46498 | F15: =IF(OR($O$6+24<$O$4,$O$6+24>$O$5),"",$O$6+24) -> 46499 | G15: =IF(OR($O$6+25<$O$4,$O$6+25>$O$5),"",$O$6+25) -> 46500 | H15: =IF(OR($O$6+26<$O$4,$O$6+26>$O$5),"",$O$6+26) -> 46501 | I15: =IF(OR($O$6+27<$O$4,$O$6+27>$O$5),"",$O$6+27) -> 46502 | N15: PROGRAMME DE LA ROUTE FILTREE (auto - alimente la grille) | W15: mars 2028 | X15: =DATE(2028,3,1) -> 46813 | Z15: TMMRUN
B16: Semaine 5 | C16: =IF(C17="","",TRIM($O$17&IF(SUMIFS($E$521:$E$560,$C$521:$C$560,$C$5,$B$521:$B$560,C17)=0,""," (+"&IF(COUNTIFS($C$521:$C$560,$C$5,$B$521:$B$560,C17)=1,IF(SUMIFS($E$521:$E$560,$C$521:$C$560,$C$5,$B$521:$B$560,C17)=1,IFERROR(INDEX($D$521:$D$560,MATCH(C17&"|"&$C$5,$H$521:$H$560,0)),""),SUMIFS($E$521:$E$560,$C$521:$C$560,$C$5,$B$521:$B$560,C17)&"x"&IFERROR(INDEX($D$521:$D$560,MATCH(C17&"|"&$C$5,$H$521:$H$560,0)),"")),SUMIFS($E$521:$E$560,$C$521:$C$560,$C$5,$B$521:$B$560,C17)&" vols")&")"))) -> A320 | D16: =IF(D17="","",TRIM($P$17&IF(SUMIFS($E$521:$E$560,$C$521:$C$560,$C$5,$B$521:$B$560,D17)=0,""," (+"&IF(COUNTIFS($C$521:$C$560,$C$5,$B$521:$B$560,D17)=1,IF(SUMIFS($E$521:$E$560,$C$521:$C$560,$C$5,$B$521:$B$560,D17)=1,IFERROR(INDEX($D$521:$D$560,MATCH(D17&"|"&$C$5,$H$521:$H$560,0)),""),SUMIFS($E$521:$E$560,$C$521:$C$560,$C$5,$B$521:$B$560,D17)&"x"&IFERROR(INDEX($D$521:$D$560,MATCH(D17&"|"&$C$5,$H$521:$H$560,0)),"")),SUMIFS($E$521:$E$560,$C$521:$C$560,$C$5,$B$521:$B$560,D17)&" vols")&")"))) | E16: =IF(E17="","",TRIM($Q$17&IF(SUMIFS($E$521:$E$560,$C$521:$C$560,$C$5,$B$521:$B$560,E17)=0,""," (+"&IF(COUNTIFS($C$521:$C$560,$C$5,$B$521:$B$560,E17)=1,IF(SUMIFS($E$521:$E$560,$C$521:$C$560,$C$5,$B$521:$B$560,E17)=1,IFERROR(INDEX($D$521:$D$560,MATCH(E17&"|"&$C$5,$H$521:$H$560,0)),""),SUMIFS($E$521:$E$560,$C$521:$C$560,$C$5,$B$521:$B$560,E17)&"x"&IFERROR(INDEX($D$521:$D$560,MATCH(E17&"|"&$C$5,$H$521:$H$560,0)),"")),SUMIFS($E$521:$E$560,$C$521:$C$560,$C$5,$B$521:$B$560,E17)&" vols")&")"))) | F16: =IF(F17="","",TRIM($R$17&IF(SUMIFS($E$521:$E$560,$C$521:$C$560,$C$5,$B$521:$B$560,F17)=0,""," (+"&IF(COUNTIFS($C$521:$C$560,$C$5,$B$521:$B$560,F17)=1,IF(SUMIFS($E$521:$E$560,$C$521:$C$560,$C$5,$B$521:$B$560,F17)=1,IFERROR(INDEX($D$521:$D$560,MATCH(F17&"|"&$C$5,$H$521:$H$560,0)),""),SUMIFS($E$521:$E$560,$C$521:$C$560,$C$5,$B$521:$B$560,F17)&"x"&IFERROR(INDEX($D$521:$D$560,MATCH(F17&"|"&$C$5,$H$521:$H$560,0)),"")),SUMIFS($E$521:$E$560,$C$521:$C$560,$C$5,$B$521:$B$560,F17)&" vols")&")"))) -> A320 | G16: =IF(G17="","",TRIM($S$17&IF(SUMIFS($E$521:$E$560,$C$521:$C$560,$C$5,$B$521:$B$560,G17)=0,""," (+"&IF(COUNTIFS($C$521:$C$560,$C$5,$B$521:$B$560,G17)=1,IF(SUMIFS($E$521:$E$560,$C$521:$C$560,$C$5,$B$521:$B$560,G17)=1,IFERROR(INDEX($D$521:$D$560,MATCH(G17&"|"&$C$5,$H$521:$H$560,0)),""),SUMIFS($E$521:$E$560,$C$521:$C$560,$C$5,$B$521:$B$560,G17)&"x"&IFERROR(INDEX($D$521:$D$560,MATCH(G17&"|"&$C$5,$H$521:$H$560,0)),"")),SUMIFS($E$521:$E$560,$C$521:$C$560,$C$5,$B$521:$B$560,G17)&" vols")&")"))) | H16: =IF(H17="","",TRIM($T$17&IF(SUMIFS($E$521:$E$560,$C$521:$C$560,$C$5,$B$521:$B$560,H17)=0,""," (+"&IF(COUNTIFS($C$521:$C$560,$C$5,$B$521:$B$560,H17)=1,IF(SUMIFS($E$521:$E$560,$C$521:$C$560,$C$5,$B$521:$B$560,H17)=1,IFERROR(INDEX($D$521:$D$560,MATCH(H17&"|"&$C$5,$H$521:$H$560,0)),""),SUMIFS($E$521:$E$560,$C$521:$C$560,$C$5,$B$521:$B$560,H17)&"x"&IFERROR(INDEX($D$521:$D$560,MATCH(H17&"|"&$C$5,$H$521:$H$560,0)),"")),SUMIFS($E$521:$E$560,$C$521:$C$560,$C$5,$B$521:$B$560,H17)&" vols")&")"))) | I16: =IF(I17="","",TRIM($U$17&IF(SUMIFS($E$521:$E$560,$C$521:$C$560,$C$5,$B$521:$B$560,I17)=0,""," (+"&IF(COUNTIFS($C$521:$C$560,$C$5,$B$521:$B$560,I17)=1,IF(SUMIFS($E$521:$E$560,$C$521:$C$560,$C$5,$B$521:$B$560,I17)=1,IFERROR(INDEX($D$521:$D$560,MATCH(I17&"|"&$C$5,$H$521:$H$560,0)),""),SUMIFS($E$521:$E$560,$C$521:$C$560,$C$5,$B$521:$B$560,I17)&"x"&IFERROR(INDEX($D$521:$D$560,MATCH(I17&"|"&$C$5,$H$521:$H$560,0)),"")),SUMIFS($E$521:$E$560,$C$521:$C$560,$C$5,$B$521:$B$560,I17)&" vols")&")"))) | N16: Jour | O16: J1 | P16: J2 | Q16: J3 | R16: J4 | S16: J5 | T16: J6 | U16: J7
B17: =IF(COUNT(C17:I17)=0,"","du "&TEXT(MIN(C17:I17),"DD/MM")&" au "&TEXT(MAX(C17:I17),"DD/MM")) -> du 26/04 au 30/04 | C17: =IF(OR($O$6+28<$O$4,$O$6+28>$O$5),"",$O$6+28) -> 46503 | D17: =IF(OR($O$6+29<$O$4,$O$6+29>$O$5),"",$O$6+29) -> 46504 | E17: =IF(OR($O$6+30<$O$4,$O$6+30>$O$5),"",$O$6+30) -> 46505 | F17: =IF(OR($O$6+31<$O$4,$O$6+31>$O$5),"",$O$6+31) -> 46506 | G17: =IF(OR($O$6+32<$O$4,$O$6+32>$O$5),"",$O$6+32) -> 46507 | H17: =IF(OR($O$6+33<$O$4,$O$6+33>$O$5),"",$O$6+33) | I17: =IF(OR($O$6+34<$O$4,$O$6+34>$O$5),"",$O$6+34) | N17: Vols du jour (affichage grille) | O17: =IF(O$18="","","77W")&IF(O$19="","",IF(O$18="","","/")&"778")&IF(O$20="","",IF(AND(O$18="",O$19=""),"","/")&"A320") -> A320 | P17: =IF(P$18="","","77W")&IF(P$19="","",IF(P$18="","","/")&"778")&IF(P$20="","",IF(AND(P$18="",P$19=""),"","/")&"A320") | Q17: =IF(Q$18="","","77W")&IF(Q$19="","",IF(Q$18="","","/")&"778")&IF(Q$20="","",IF(AND(Q$18="",Q$19=""),"","/")&"A320") | R17: =IF(R$18="","","77W")&IF(R$19="","",IF(R$18="","","/")&"778")&IF(R$20="","",IF(AND(R$18="",R$19=""),"","/")&"A320") -> A320 | S17: =IF(S$18="","","77W")&IF(S$19="","",IF(S$18="","","/")&"778")&IF(S$20="","",IF(AND(S$18="",S$19=""),"","/")&"A320") | T17: =IF(T$18="","","77W")&IF(T$19="","",IF(T$18="","","/")&"778")&IF(T$20="","",IF(AND(T$18="",T$19=""),"","/")&"A320") -> A320 | U17: =IF(U$18="","","77W")&IF(U$19="","",IF(U$18="","","/")&"778")&IF(U$20="","",IF(AND(U$18="",U$19=""),"","/")&"A320")
B18: Semaine 6 | C18: =IF(C19="","",TRIM($O$17&IF(SUMIFS($E$521:$E$560,$C$521:$C$560,$C$5,$B$521:$B$560,C19)=0,""," (+"&IF(COUNTIFS($C$521:$C$560,$C$5,$B$521:$B$560,C19)=1,IF(SUMIFS($E$521:$E$560,$C$521:$C$560,$C$5,$B$521:$B$560,C19)=1,IFERROR(INDEX($D$521:$D$560,MATCH(C19&"|"&$C$5,$H$521:$H$560,0)),""),SUMIFS($E$521:$E$560,$C$521:$C$560,$C$5,$B$521:$B$560,C19)&"x"&IFERROR(INDEX($D$521:$D$560,MATCH(C19&"|"&$C$5,$H$521:$H$560,0)),"")),SUMIFS($E$521:$E$560,$C$521:$C$560,$C$5,$B$521:$B$560,C19)&" vols")&")"))) | D18: =IF(D19="","",TRIM($P$17&IF(SUMIFS($E$521:$E$560,$C$521:$C$560,$C$5,$B$521:$B$560,D19)=0,""," (+"&IF(COUNTIFS($C$521:$C$560,$C$5,$B$521:$B$560,D19)=1,IF(SUMIFS($E$521:$E$560,$C$521:$C$560,$C$5,$B$521:$B$560,D19)=1,IFERROR(INDEX($D$521:$D$560,MATCH(D19&"|"&$C$5,$H$521:$H$560,0)),""),SUMIFS($E$521:$E$560,$C$521:$C$560,$C$5,$B$521:$B$560,D19)&"x"&IFERROR(INDEX($D$521:$D$560,MATCH(D19&"|"&$C$5,$H$521:$H$560,0)),"")),SUMIFS($E$521:$E$560,$C$521:$C$560,$C$5,$B$521:$B$560,D19)&" vols")&")"))) | E18: =IF(E19="","",TRIM($Q$17&IF(SUMIFS($E$521:$E$560,$C$521:$C$560,$C$5,$B$521:$B$560,E19)=0,""," (+"&IF(COUNTIFS($C$521:$C$560,$C$5,$B$521:$B$560,E19)=1,IF(SUMIFS($E$521:$E$560,$C$521:$C$560,$C$5,$B$521:$B$560,E19)=1,IFERROR(INDEX($D$521:$D$560,MATCH(E19&"|"&$C$5,$H$521:$H$560,0)),""),SUMIFS($E$521:$E$560,$C$521:$C$560,$C$5,$B$521:$B$560,E19)&"x"&IFERROR(INDEX($D$521:$D$560,MATCH(E19&"|"&$C$5,$H$521:$H$560,0)),"")),SUMIFS($E$521:$E$560,$C$521:$C$560,$C$5,$B$521:$B$560,E19)&" vols")&")"))) | F18: =IF(F19="","",TRIM($R$17&IF(SUMIFS($E$521:$E$560,$C$521:$C$560,$C$5,$B$521:$B$560,F19)=0,""," (+"&IF(COUNTIFS($C$521:$C$560,$C$5,$B$521:$B$560,F19)=1,IF(SUMIFS($E$521:$E$560,$C$521:$C$560,$C$5,$B$521:$B$560,F19)=1,IFERROR(INDEX($D$521:$D$560,MATCH(F19&"|"&$C$5,$H$521:$H$560,0)),""),SUMIFS($E$521:$E$560,$C$521:$C$560,$C$5,$B$521:$B$560,F19)&"x"&IFERROR(INDEX($D$521:$D$560,MATCH(F19&"|"&$C$5,$H$521:$H$560,0)),"")),SUMIFS($E$521:$E$560,$C$521:$C$560,$C$5,$B$521:$B$560,F19)&" vols")&")"))) | G18: =IF(G19="","",TRIM($S$17&IF(SUMIFS($E$521:$E$560,$C$521:$C$560,$C$5,$B$521:$B$560,G19)=0,""," (+"&IF(COUNTIFS($C$521:$C$560,$C$5,$B$521:$B$560,G19)=1,IF(SUMIFS($E$521:$E$560,$C$521:$C$560,$C$5,$B$521:$B$560,G19)=1,IFERROR(INDEX($D$521:$D$560,MATCH(G19&"|"&$C$5,$H$521:$H$560,0)),""),SUMIFS($E$521:$E$560,$C$521:$C$560,$C$5,$B$521:$B$560,G19)&"x"&IFERROR(INDEX($D$521:$D$560,MATCH(G19&"|"&$C$5,$H$521:$H$560,0)),"")),SUMIFS($E$521:$E$560,$C$521:$C$560,$C$5,$B$521:$B$560,G19)&" vols")&")"))) | H18: =IF(H19="","",TRIM($T$17&IF(SUMIFS($E$521:$E$560,$C$521:$C$560,$C$5,$B$521:$B$560,H19)=0,""," (+"&IF(COUNTIFS($C$521:$C$560,$C$5,$B$521:$B$560,H19)=1,IF(SUMIFS($E$521:$E$560,$C$521:$C$560,$C$5,$B$521:$B$560,H19)=1,IFERROR(INDEX($D$521:$D$560,MATCH(H19&"|"&$C$5,$H$521:$H$560,0)),""),SUMIFS($E$521:$E$560,$C$521:$C$560,$C$5,$B$521:$B$560,H19)&"x"&IFERROR(INDEX($D$521:$D$560,MATCH(H19&"|"&$C$5,$H$521:$H$560,0)),"")),SUMIFS($E$521:$E$560,$C$521:$C$560,$C$5,$B$521:$B$560,H19)&" vols")&")"))) | I18: =IF(I19="","",TRIM($U$17&IF(SUMIFS($E$521:$E$560,$C$521:$C$560,$C$5,$B$521:$B$560,I19)=0,""," (+"&IF(COUNTIFS($C$521:$C$560,$C$5,$B$521:$B$560,I19)=1,IF(SUMIFS($E$521:$E$560,$C$521:$C$560,$C$5,$B$521:$B$560,I19)=1,IFERROR(INDEX($D$521:$D$560,MATCH(I19&"|"&$C$5,$H$521:$H$560,0)),""),SUMIFS($E$521:$E$560,$C$521:$C$560,$C$5,$B$521:$B$560,I19)&"x"&IFERROR(INDEX($D$521:$D$560,MATCH(I19&"|"&$C$5,$H$521:$H$560,0)),"")),SUMIFS($E$521:$E$560,$C$521:$C$560,$C$5,$B$521:$B$560,I19)&" vols")&")"))) | N18: 77W opere ? | O18: =IFERROR(INDEX($O$24:$U$59,(MATCH($C$5,$Z$4:$Z$15,0)-1)*3+1,1)&"","") | P18: =IFERROR(INDEX($O$24:$U$59,(MATCH($C$5,$Z$4:$Z$15,0)-1)*3+1,2)&"","") | Q18: =IFERROR(INDEX($O$24:$U$59,(MATCH($C$5,$Z$4:$Z$15,0)-1)*3+1,3)&"","") | R18: =IFERROR(INDEX($O$24:$U$59,(MATCH($C$5,$Z$4:$Z$15,0)-1)*3+1,4)&"","") | S18: =IFERROR(INDEX($O$24:$U$59,(MATCH($C$5,$Z$4:$Z$15,0)-1)*3+1,5)&"","") | T18: =IFERROR(INDEX($O$24:$U$59,(MATCH($C$5,$Z$4:$Z$15,0)-1)*3+1,6)&"","") | U18: =IFERROR(INDEX($O$24:$U$59,(MATCH($C$5,$Z$4:$Z$15,0)-1)*3+1,7)&"","")
B19: =IF(COUNT(C19:I19)=0,"","du "&TEXT(MIN(C19:I19),"DD/MM")&" au "&TEXT(MAX(C19:I19),"DD/MM")) | C19: =IF(OR($O$6+35<$O$4,$O$6+35>$O$5),"",$O$6+35) | D19: =IF(OR($O$6+36<$O$4,$O$6+36>$O$5),"",$O$6+36) | E19: =IF(OR($O$6+37<$O$4,$O$6+37>$O$5),"",$O$6+37) | F19: =IF(OR($O$6+38<$O$4,$O$6+38>$O$5),"",$O$6+38) | G19: =IF(OR($O$6+39<$O$4,$O$6+39>$O$5),"",$O$6+39) | H19: =IF(OR($O$6+40<$O$4,$O$6+40>$O$5),"",$O$6+40) | I19: =IF(OR($O$6+41<$O$4,$O$6+41>$O$5),"",$O$6+41) | N19: 778 opere ? | O19: =IFERROR(INDEX($O$24:$U$59,(MATCH($C$5,$Z$4:$Z$15,0)-1)*3+2,1)&"","") | P19: =IFERROR(INDEX($O$24:$U$59,(MATCH($C$5,$Z$4:$Z$15,0)-1)*3+2,2)&"","") | Q19: =IFERROR(INDEX($O$24:$U$59,(MATCH($C$5,$Z$4:$Z$15,0)-1)*3+2,3)&"","") | R19: =IFERROR(INDEX($O$24:$U$59,(MATCH($C$5,$Z$4:$Z$15,0)-1)*3+2,4)&"","") | S19: =IFERROR(INDEX($O$24:$U$59,(MATCH($C$5,$Z$4:$Z$15,0)-1)*3+2,5)&"","") | T19: =IFERROR(INDEX($O$24:$U$59,(MATCH($C$5,$Z$4:$Z$15,0)-1)*3+2,6)&"","") | U19: =IFERROR(INDEX($O$24:$U$59,(MATCH($C$5,$Z$4:$Z$15,0)-1)*3+2,7)&"","")
B20: Occurrences du jour dans le mois | C20: =COUNT(C9,C11,C13,C15,C17,C19) -> 4 | D20: =COUNT(D9,D11,D13,D15,D17,D19) -> 4 | E20: =COUNT(E9,E11,E13,E15,E17,E19) -> 4 | F20: =COUNT(F9,F11,F13,F15,F17,F19) -> 5 | G20: =COUNT(G9,G11,G13,G15,G17,G19) -> 5 | H20: =COUNT(H9,H11,H13,H15,H17,H19) -> 4 | I20: =COUNT(I9,I11,I13,I15,I17,I19) -> 4 | N20: A320 opere ? | O20: =IFERROR(INDEX($O$24:$U$59,(MATCH($C$5,$Z$4:$Z$15,0)-1)*3+3,1)&"","") -> x | P20: =IFERROR(INDEX($O$24:$U$59,(MATCH($C$5,$Z$4:$Z$15,0)-1)*3+3,2)&"","") | Q20: =IFERROR(INDEX($O$24:$U$59,(MATCH($C$5,$Z$4:$Z$15,0)-1)*3+3,3)&"","") | R20: =IFERROR(INDEX($O$24:$U$59,(MATCH($C$5,$Z$4:$Z$15,0)-1)*3+3,4)&"","") -> x | S20: =IFERROR(INDEX($O$24:$U$59,(MATCH($C$5,$Z$4:$Z$15,0)-1)*3+3,5)&"","") | T20: =IFERROR(INDEX($O$24:$U$59,(MATCH($C$5,$Z$4:$Z$15,0)-1)*3+3,6)&"","") -> x | U20: =IFERROR(INDEX($O$24:$U$59,(MATCH($C$5,$Z$4:$Z$15,0)-1)*3+3,7)&"","")
B21: Nb de semaines calendaires du mois | C21: =IF(COUNT(C9:I9)>0,1,0)+IF(COUNT(C11:I11)>0,1,0)+IF(COUNT(C13:I13)>0,1,0)+IF(COUNT(C15:I15)>0,1,0)+IF(COUNT(C17:I17)>0,1,0)+IF(COUNT(C19:I19)>0,1,0) -> 5 | D21: Lecture : "778" = 1 vol du programme | "77W/778/A320" = 2 ou 3 vols le meme jour | "778 (+A320)" = programme + vol additionnel (bordure rouge) | "(+A320)" = vol additionnel seul.
N22: PROGRAMME DU MOIS FILTRE, TOUTES ROUTES (auto - recopie du tableau du mois)
B23: RECAPITULATIF MENSUEL - TOUTES ROUTES (depend uniquement du filtre Mois) | N23: Route / type | O23: J1 | P23: J2 | Q23: J3 | R23: J4 | S23: J5 | T23: J6 | U23: J7
B24: Route | C24: Type(s) avion | D24: Semaine type du mois (jours J1-J7) | E24: Rotations/semaine | F24: Nb de semaines/occurrences dans le mois | G24: Total rotations du mois | H24: dont programme du mois | I24: dont vols additionnels | J24: Total 77W | K24: Total 778 | L24: Total A320 | N24: CDGRUN - 77W | O24: =IFERROR(INDEX($D$49:$J$513,($O$7-1)*39+1,1)&"","") -> x | P24: =IFERROR(INDEX($D$49:$J$513,($O$7-1)*39+1,2)&"","") -> x | Q24: =IFERROR(INDEX($D$49:$J$513,($O$7-1)*39+1,3)&"","") -> x | R24: =IFERROR(INDEX($D$49:$J$513,($O$7-1)*39+1,4)&"","") -> x | S24: =IFERROR(INDEX($D$49:$J$513,($O$7-1)*39+1,5)&"","") -> x | T24: =IFERROR(INDEX($D$49:$J$513,($O$7-1)*39+1,6)&"","") -> x | U24: =IFERROR(INDEX($D$49:$J$513,($O$7-1)*39+1,7)&"","") -> x
B25: =$Z$4 -> CDGRUN | C25: =IF(E25=0,"-",SUBSTITUTE(TRIM(IF(SUMPRODUCT(--($O$24:$U$24<>""))>0,"77W("&SUMPRODUCT(--($O$24:$U$24<>""))&") ","")&IF(SUMPRODUCT(--($O$25:$U$25<>""))>0,"778("&SUMPRODUCT(--($O$25:$U$25<>""))&") ","")&IF(SUMPRODUCT(--($O$26:$U$26<>""))>0,"A320("&SUMPRODUCT(--($O$26:$U$26<>""))&") ",""))," ",", ")) -> 77W(7), 778(2), A320(1) | D25: =IF(E25=0,"aucune operation",SUBSTITUTE(TRIM(IF(SUMPRODUCT(--($O$24:$O$26<>""))>0,"J1 ","")&IF(SUMPRODUCT(--($P$24:$P$26<>""))>0,"J2 ","")&IF(SUMPRODUCT(--($Q$24:$Q$26<>""))>0,"J3 ","")&IF(SUMPRODUCT(--($R$24:$R$26<>""))>0,"J4 ","")&IF(SUMPRODUCT(--($S$24:$S$26<>""))>0,"J5 ","")&IF(SUMPRODUCT(--($T$24:$T$26<>""))>0,"J6 ","")&IF(SUMPRODUCT(--($U$24:$U$26<>""))>0,"J7 ",""))," ",", ")) -> J1, J2, J3, J4, J5, J6, J7 | E25: =SUMPRODUCT(--($O$24:$U$26<>"")) -> 10 | F25: =$C$21 -> 5 | G25: =H25+I25 -> 45 | H25: =SUMPRODUCT($C$20:$I$20,--($O$24:$U$24<>""))+SUMPRODUCT($C$20:$I$20,--($O$25:$U$25<>""))+SUMPRODUCT($C$20:$I$20,--($O$26:$U$26<>"")) -> 43 | I25: =SUMIFS($E$521:$E$560,$C$521:$C$560,$B25,$B$521:$B$560,">="&$O$4,$B$521:$B$560,"<="&$O$5) -> 2 | J25: =SUMPRODUCT($C$20:$I$20,--($O$24:$U$24<>""))+SUMIFS($E$521:$E$560,$C$521:$C$560,$B25,$D$521:$D$560,"77W",$B$521:$B$560,">="&$O$4,$B$521:$B$560,"<="&$O$5) -> 30 | K25: =SUMPRODUCT($C$20:$I$20,--($O$25:$U$25<>""))+SUMIFS($E$521:$E$560,$C$521:$C$560,$B25,$D$521:$D$560,"778",$B$521:$B$560,">="&$O$4,$B$521:$B$560,"<="&$O$5) -> 11 | L25: =SUMPRODUCT($C$20:$I$20,--($O$26:$U$26<>""))+SUMIFS($E$521:$E$560,$C$521:$C$560,$B25,$D$521:$D$560,"A320",$B$521:$B$560,">="&$O$4,$B$521:$B$560,"<="&$O$5) -> 4 | N25: CDGRUN - 778 | O25: =IFERROR(INDEX($D$49:$J$513,($O$7-1)*39+2,1)&"","") -> x | P25: =IFERROR(INDEX($D$49:$J$513,($O$7-1)*39+2,2)&"","") | Q25: =IFERROR(INDEX($D$49:$J$513,($O$7-1)*39+2,3)&"","") | R25: =IFERROR(INDEX($D$49:$J$513,($O$7-1)*39+2,4)&"","") | S25: =IFERROR(INDEX($D$49:$J$513,($O$7-1)*39+2,5)&"","") -> x | T25: =IFERROR(INDEX($D$49:$J$513,($O$7-1)*39+2,6)&"","") | U25: =IFERROR(INDEX($D$49:$J$513,($O$7-1)*39+2,7)&"","")
B26: =$Z$5 -> CDGDZA | C26: =IF(E26=0,"-",SUBSTITUTE(TRIM(IF(SUMPRODUCT(--($O$27:$U$27<>""))>0,"77W("&SUMPRODUCT(--($O$27:$U$27<>""))&") ","")&IF(SUMPRODUCT(--($O$28:$U$28<>""))>0,"778("&SUMPRODUCT(--($O$28:$U$28<>""))&") ","")&IF(SUMPRODUCT(--($O$29:$U$29<>""))>0,"A320("&SUMPRODUCT(--($O$29:$U$29<>""))&") ",""))," ",", ")) -> 77W(1), 778(2) | D26: =IF(E26=0,"aucune operation",SUBSTITUTE(TRIM(IF(SUMPRODUCT(--($O$27:$O$29<>""))>0,"J1 ","")&IF(SUMPRODUCT(--($P$27:$P$29<>""))>0,"J2 ","")&IF(SUMPRODUCT(--($Q$27:$Q$29<>""))>0,"J3 ","")&IF(SUMPRODUCT(--($R$27:$R$29<>""))>0,"J4 ","")&IF(SUMPRODUCT(--($S$27:$S$29<>""))>0,"J5 ","")&IF(SUMPRODUCT(--($T$27:$T$29<>""))>0,"J6 ","")&IF(SUMPRODUCT(--($U$27:$U$29<>""))>0,"J7 ",""))," ",", ")) -> J2, J5, J7 | E26: =SUMPRODUCT(--($O$27:$U$29<>"")) -> 3 | F26: =$C$21 -> 5 | G26: =H26+I26 -> 13 | H26: =SUMPRODUCT($C$20:$I$20,--($O$27:$U$27<>""))+SUMPRODUCT($C$20:$I$20,--($O$28:$U$28<>""))+SUMPRODUCT($C$20:$I$20,--($O$29:$U$29<>"")) -> 13 | I26: =SUMIFS($E$521:$E$560,$C$521:$C$560,$B26,$B$521:$B$560,">="&$O$4,$B$521:$B$560,"<="&$O$5) -> 0 | J26: =SUMPRODUCT($C$20:$I$20,--($O$27:$U$27<>""))+SUMIFS($E$521:$E$560,$C$521:$C$560,$B26,$D$521:$D$560,"77W",$B$521:$B$560,">="&$O$4,$B$521:$B$560,"<="&$O$5) -> 4 | K26: =SUMPRODUCT($C$20:$I$20,--($O$28:$U$28<>""))+SUMIFS($E$521:$E$560,$C$521:$C$560,$B26,$D$521:$D$560,"778",$B$521:$B$560,">="&$O$4,$B$521:$B$560,"<="&$O$5) -> 9 | L26: =SUMPRODUCT($C$20:$I$20,--($O$29:$U$29<>""))+SUMIFS($E$521:$E$560,$C$521:$C$560,$B26,$D$521:$D$560,"A320",$B$521:$B$560,">="&$O$4,$B$521:$B$560,"<="&$O$5) -> 0 | N26: CDGRUN - A320 | O26: =IFERROR(INDEX($D$49:$J$513,($O$7-1)*39+3,1)&"","") -> x | P26: =IFERROR(INDEX($D$49:$J$513,($O$7-1)*39+3,2)&"","") | Q26: =IFERROR(INDEX($D$49:$J$513,($O$7-1)*39+3,3)&"","") | R26: =IFERROR(INDEX($D$49:$J$513,($O$7-1)*39+3,4)&"","") | S26: =IFERROR(INDEX($D$49:$J$513,($O$7-1)*39+3,5)&"","") | T26: =IFERROR(INDEX($D$49:$J$513,($O$7-1)*39+3,6)&"","") | U26: =IFERROR(INDEX($D$49:$J$513,($O$7-1)*39+3,7)&"","")
B27: =$Z$6 -> BKKRUN | C27: =IF(E27=0,"-",SUBSTITUTE(TRIM(IF(SUMPRODUCT(--($O$30:$U$30<>""))>0,"77W("&SUMPRODUCT(--($O$30:$U$30<>""))&") ","")&IF(SUMPRODUCT(--($O$31:$U$31<>""))>0,"778("&SUMPRODUCT(--($O$31:$U$31<>""))&") ","")&IF(SUMPRODUCT(--($O$32:$U$32<>""))>0,"A320("&SUMPRODUCT(--($O$32:$U$32<>""))&") ",""))," ",", ")) -> 778(2) | D27: =IF(E27=0,"aucune operation",SUBSTITUTE(TRIM(IF(SUMPRODUCT(--($O$30:$O$32<>""))>0,"J1 ","")&IF(SUMPRODUCT(--($P$30:$P$32<>""))>0,"J2 ","")&IF(SUMPRODUCT(--($Q$30:$Q$32<>""))>0,"J3 ","")&IF(SUMPRODUCT(--($R$30:$R$32<>""))>0,"J4 ","")&IF(SUMPRODUCT(--($S$30:$S$32<>""))>0,"J5 ","")&IF(SUMPRODUCT(--($T$30:$T$32<>""))>0,"J6 ","")&IF(SUMPRODUCT(--($U$30:$U$32<>""))>0,"J7 ",""))," ",", ")) -> J3, J6 | E27: =SUMPRODUCT(--($O$30:$U$32<>"")) -> 2 | F27: =$C$21 -> 5 | G27: =H27+I27 -> 8 | H27: =SUMPRODUCT($C$20:$I$20,--($O$30:$U$30<>""))+SUMPRODUCT($C$20:$I$20,--($O$31:$U$31<>""))+SUMPRODUCT($C$20:$I$20,--($O$32:$U$32<>"")) -> 8 | I27: =SUMIFS($E$521:$E$560,$C$521:$C$560,$B27,$B$521:$B$560,">="&$O$4,$B$521:$B$560,"<="&$O$5) -> 0 | J27: =SUMPRODUCT($C$20:$I$20,--($O$30:$U$30<>""))+SUMIFS($E$521:$E$560,$C$521:$C$560,$B27,$D$521:$D$560,"77W",$B$521:$B$560,">="&$O$4,$B$521:$B$560,"<="&$O$5) -> 0 | K27: =SUMPRODUCT($C$20:$I$20,--($O$31:$U$31<>""))+SUMIFS($E$521:$E$560,$C$521:$C$560,$B27,$D$521:$D$560,"778",$B$521:$B$560,">="&$O$4,$B$521:$B$560,"<="&$O$5) -> 8 | L27: =SUMPRODUCT($C$20:$I$20,--($O$32:$U$32<>""))+SUMIFS($E$521:$E$560,$C$521:$C$560,$B27,$D$521:$D$560,"A320",$B$521:$B$560,">="&$O$4,$B$521:$B$560,"<="&$O$5) -> 0 | N27: CDGDZA - 77W | O27: =IFERROR(INDEX($D$49:$J$513,($O$7-1)*39+4,1)&"","") | P27: =IFERROR(INDEX($D$49:$J$513,($O$7-1)*39+4,2)&"","") | Q27: =IFERROR(INDEX($D$49:$J$513,($O$7-1)*39+4,3)&"","") | R27: =IFERROR(INDEX($D$49:$J$513,($O$7-1)*39+4,4)&"","") | S27: =IFERROR(INDEX($D$49:$J$513,($O$7-1)*39+4,5)&"","") | T27: =IFERROR(INDEX($D$49:$J$513,($O$7-1)*39+4,6)&"","") | U27: =IFERROR(INDEX($D$49:$J$513,($O$7-1)*39+4,7)&"","") -> x
B28: =$Z$7 -> DZARUN | C28: =IF(E28=0,"-",SUBSTITUTE(TRIM(IF(SUMPRODUCT(--($O$33:$U$33<>""))>0,"77W("&SUMPRODUCT(--($O$33:$U$33<>""))&") ","")&IF(SUMPRODUCT(--($O$34:$U$34<>""))>0,"778("&SUMPRODUCT(--($O$34:$U$34<>""))&") ","")&IF(SUMPRODUCT(--($O$35:$U$35<>""))>0,"A320("&SUMPRODUCT(--($O$35:$U$35<>""))&") ",""))," ",", ")) -> 778(1), A320(5) | D28: =IF(E28=0,"aucune operation",SUBSTITUTE(TRIM(IF(SUMPRODUCT(--($O$33:$O$35<>""))>0,"J1 ","")&IF(SUMPRODUCT(--($P$33:$P$35<>""))>0,"J2 ","")&IF(SUMPRODUCT(--($Q$33:$Q$35<>""))>0,"J3 ","")&IF(SUMPRODUCT(--($R$33:$R$35<>""))>0,"J4 ","")&IF(SUMPRODUCT(--($S$33:$S$35<>""))>0,"J5 ","")&IF(SUMPRODUCT(--($T$33:$T$35<>""))>0,"J6 ","")&IF(SUMPRODUCT(--($U$33:$U$35<>""))>0,"J7 ",""))," ",", ")) -> J1, J2, J3, J4, J5 | E28: =SUMPRODUCT(--($O$33:$U$35<>"")) -> 6 | F28: =$C$21 -> 5 | G28: =H28+I28 -> 26 | H28: =SUMPRODUCT($C$20:$I$20,--($O$33:$U$33<>""))+SUMPRODUCT($C$20:$I$20,--($O$34:$U$34<>""))+SUMPRODUCT($C$20:$I$20,--($O$35:$U$35<>"")) -> 26 | I28: =SUMIFS($E$521:$E$560,$C$521:$C$560,$B28,$B$521:$B$560,">="&$O$4,$B$521:$B$560,"<="&$O$5) -> 0 | J28: =SUMPRODUCT($C$20:$I$20,--($O$33:$U$33<>""))+SUMIFS($E$521:$E$560,$C$521:$C$560,$B28,$D$521:$D$560,"77W",$B$521:$B$560,">="&$O$4,$B$521:$B$560,"<="&$O$5) -> 0 | K28: =SUMPRODUCT($C$20:$I$20,--($O$34:$U$34<>""))+SUMIFS($E$521:$E$560,$C$521:$C$560,$B28,$D$521:$D$560,"778",$B$521:$B$560,">="&$O$4,$B$521:$B$560,"<="&$O$5) -> 4 | L28: =SUMPRODUCT($C$20:$I$20,--($O$35:$U$35<>""))+SUMIFS($E$521:$E$560,$C$521:$C$560,$B28,$D$521:$D$560,"A320",$B$521:$B$560,">="&$O$4,$B$521:$B$560,"<="&$O$5) -> 22 | N28: CDGDZA - 778 | O28: =IFERROR(INDEX($D$49:$J$513,($O$7-1)*39+5,1)&"","") | P28: =IFERROR(INDEX($D$49:$J$513,($O$7-1)*39+5,2)&"","") -> x | Q28: =IFERROR(INDEX($D$49:$J$513,($O$7-1)*39+5,3)&"","") | R28: =IFERROR(INDEX($D$49:$J$513,($O$7-1)*39+5,4)&"","") | S28: =IFERROR(INDEX($D$49:$J$513,($O$7-1)*39+5,5)&"","") -> x | T28: =IFERROR(INDEX($D$49:$J$513,($O$7-1)*39+5,6)&"","") | U28: =IFERROR(INDEX($D$49:$J$513,($O$7-1)*39+5,7)&"","")
B29: =$Z$8 -> MRURUN | C29: =IF(E29=0,"-",SUBSTITUTE(TRIM(IF(SUMPRODUCT(--($O$36:$U$36<>""))>0,"77W("&SUMPRODUCT(--($O$36:$U$36<>""))&") ","")&IF(SUMPRODUCT(--($O$37:$U$37<>""))>0,"778("&SUMPRODUCT(--($O$37:$U$37<>""))&") ","")&IF(SUMPRODUCT(--($O$38:$U$38<>""))>0,"A320("&SUMPRODUCT(--($O$38:$U$38<>""))&") ",""))," ",", ")) -> A320(4) | D29: =IF(E29=0,"aucune operation",SUBSTITUTE(TRIM(IF(SUMPRODUCT(--($O$36:$O$38<>""))>0,"J1 ","")&IF(SUMPRODUCT(--($P$36:$P$38<>""))>0,"J2 ","")&IF(SUMPRODUCT(--($Q$36:$Q$38<>""))>0,"J3 ","")&IF(SUMPRODUCT(--($R$36:$R$38<>""))>0,"J4 ","")&IF(SUMPRODUCT(--($S$36:$S$38<>""))>0,"J5 ","")&IF(SUMPRODUCT(--($T$36:$T$38<>""))>0,"J6 ","")&IF(SUMPRODUCT(--($U$36:$U$38<>""))>0,"J7 ",""))," ",", ")) -> J1, J3, J5, J7 | E29: =SUMPRODUCT(--($O$36:$U$38<>"")) -> 4 | F29: =$C$21 -> 5 | G29: =H29+I29 -> 17 | H29: =SUMPRODUCT($C$20:$I$20,--($O$36:$U$36<>""))+SUMPRODUCT($C$20:$I$20,--($O$37:$U$37<>""))+SUMPRODUCT($C$20:$I$20,--($O$38:$U$38<>"")) -> 17 | I29: =SUMIFS($E$521:$E$560,$C$521:$C$560,$B29,$B$521:$B$560,">="&$O$4,$B$521:$B$560,"<="&$O$5) -> 0 | J29: =SUMPRODUCT($C$20:$I$20,--($O$36:$U$36<>""))+SUMIFS($E$521:$E$560,$C$521:$C$560,$B29,$D$521:$D$560,"77W",$B$521:$B$560,">="&$O$4,$B$521:$B$560,"<="&$O$5) -> 0 | K29: =SUMPRODUCT($C$20:$I$20,--($O$37:$U$37<>""))+SUMIFS($E$521:$E$560,$C$521:$C$560,$B29,$D$521:$D$560,"778",$B$521:$B$560,">="&$O$4,$B$521:$B$560,"<="&$O$5) -> 0 | L29: =SUMPRODUCT($C$20:$I$20,--($O$38:$U$38<>""))+SUMIFS($E$521:$E$560,$C$521:$C$560,$B29,$D$521:$D$560,"A320",$B$521:$B$560,">="&$O$4,$B$521:$B$560,"<="&$O$5) -> 17 | N29: CDGDZA - A320 | O29: =IFERROR(INDEX($D$49:$J$513,($O$7-1)*39+6,1)&"","") | P29: =IFERROR(INDEX($D$49:$J$513,($O$7-1)*39+6,2)&"","") | Q29: =IFERROR(INDEX($D$49:$J$513,($O$7-1)*39+6,3)&"","") | R29: =IFERROR(INDEX($D$49:$J$513,($O$7-1)*39+6,4)&"","") | S29: =IFERROR(INDEX($D$49:$J$513,($O$7-1)*39+6,5)&"","") | T29: =IFERROR(INDEX($D$49:$J$513,($O$7-1)*39+6,6)&"","") | U29: =IFERROR(INDEX($D$49:$J$513,($O$7-1)*39+6,7)&"","")
B30: =$Z$9 -> NOSRUN | C30: =IF(E30=0,"-",SUBSTITUTE(TRIM(IF(SUMPRODUCT(--($O$39:$U$39<>""))>0,"77W("&SUMPRODUCT(--($O$39:$U$39<>""))&") ","")&IF(SUMPRODUCT(--($O$40:$U$40<>""))>0,"778("&SUMPRODUCT(--($O$40:$U$40<>""))&") ","")&IF(SUMPRODUCT(--($O$41:$U$41<>""))>0,"A320("&SUMPRODUCT(--($O$41:$U$41<>""))&") ",""))," ",", ")) -> A320(3) | D30: =IF(E30=0,"aucune operation",SUBSTITUTE(TRIM(IF(SUMPRODUCT(--($O$39:$O$41<>""))>0,"J1 ","")&IF(SUMPRODUCT(--($P$39:$P$41<>""))>0,"J2 ","")&IF(SUMPRODUCT(--($Q$39:$Q$41<>""))>0,"J3 ","")&IF(SUMPRODUCT(--($R$39:$R$41<>""))>0,"J4 ","")&IF(SUMPRODUCT(--($S$39:$S$41<>""))>0,"J5 ","")&IF(SUMPRODUCT(--($T$39:$T$41<>""))>0,"J6 ","")&IF(SUMPRODUCT(--($U$39:$U$41<>""))>0,"J7 ",""))," ",", ")) -> J1, J4, J6 | E30: =SUMPRODUCT(--($O$39:$U$41<>"")) -> 3 | F30: =$C$21 -> 5 | G30: =H30+I30 -> 15 | H30: =SUMPRODUCT($C$20:$I$20,--($O$39:$U$39<>""))+SUMPRODUCT($C$20:$I$20,--($O$40:$U$40<>""))+SUMPRODUCT($C$20:$I$20,--($O$41:$U$41<>"")) -> 13 | I30: =SUMIFS($E$521:$E$560,$C$521:$C$560,$B30,$B$521:$B$560,">="&$O$4,$B$521:$B$560,"<="&$O$5) -> 2 | J30: =SUMPRODUCT($C$20:$I$20,--($O$39:$U$39<>""))+SUMIFS($E$521:$E$560,$C$521:$C$560,$B30,$D$521:$D$560,"77W",$B$521:$B$560,">="&$O$4,$B$521:$B$560,"<="&$O$5) -> 0 | K30: =SUMPRODUCT($C$20:$I$20,--($O$40:$U$40<>""))+SUMIFS($E$521:$E$560,$C$521:$C$560,$B30,$D$521:$D$560,"778",$B$521:$B$560,">="&$O$4,$B$521:$B$560,"<="&$O$5) -> 0 | L30: =SUMPRODUCT($C$20:$I$20,--($O$41:$U$41<>""))+SUMIFS($E$521:$E$560,$C$521:$C$560,$B30,$D$521:$D$560,"A320",$B$521:$B$560,">="&$O$4,$B$521:$B$560,"<="&$O$5) -> 15 | N30: BKKRUN - 77W | O30: =IFERROR(INDEX($D$49:$J$513,($O$7-1)*39+7,1)&"","") | P30: =IFERROR(INDEX($D$49:$J$513,($O$7-1)*39+7,2)&"","") | Q30: =IFERROR(INDEX($D$49:$J$513,($O$7-1)*39+7,3)&"","") | R30: =IFERROR(INDEX($D$49:$J$513,($O$7-1)*39+7,4)&"","") | S30: =IFERROR(INDEX($D$49:$J$513,($O$7-1)*39+7,5)&"","") | T30: =IFERROR(INDEX($D$49:$J$513,($O$7-1)*39+7,6)&"","") | U30: =IFERROR(INDEX($D$49:$J$513,($O$7-1)*39+7,7)&"","")
B31: =$Z$10 -> RUNTNR | C31: =IF(E31=0,"-",SUBSTITUTE(TRIM(IF(SUMPRODUCT(--($O$42:$U$42<>""))>0,"77W("&SUMPRODUCT(--($O$42:$U$42<>""))&") ","")&IF(SUMPRODUCT(--($O$43:$U$43<>""))>0,"778("&SUMPRODUCT(--($O$43:$U$43<>""))&") ","")&IF(SUMPRODUCT(--($O$44:$U$44<>""))>0,"A320("&SUMPRODUCT(--($O$44:$U$44<>""))&") ",""))," ",", ")) -> A320(3) | D31: =IF(E31=0,"aucune operation",SUBSTITUTE(TRIM(IF(SUMPRODUCT(--($O$42:$O$44<>""))>0,"J1 ","")&IF(SUMPRODUCT(--($P$42:$P$44<>""))>0,"J2 ","")&IF(SUMPRODUCT(--($Q$42:$Q$44<>""))>0,"J3 ","")&IF(SUMPRODUCT(--($R$42:$R$44<>""))>0,"J4 ","")&IF(SUMPRODUCT(--($S$42:$S$44<>""))>0,"J5 ","")&IF(SUMPRODUCT(--($T$42:$T$44<>""))>0,"J6 ","")&IF(SUMPRODUCT(--($U$42:$U$44<>""))>0,"J7 ",""))," ",", ")) -> J2, J4, J6 | E31: =SUMPRODUCT(--($O$42:$U$44<>"")) -> 3 | F31: =$C$21 -> 5 | G31: =H31+I31 -> 13 | H31: =SUMPRODUCT($C$20:$I$20,--($O$42:$U$42<>""))+SUMPRODUCT($C$20:$I$20,--($O$43:$U$43<>""))+SUMPRODUCT($C$20:$I$20,--($O$44:$U$44<>"")) -> 13 | I31: =SUMIFS($E$521:$E$560,$C$521:$C$560,$B31,$B$521:$B$560,">="&$O$4,$B$521:$B$560,"<="&$O$5) -> 0 | J31: =SUMPRODUCT($C$20:$I$20,--($O$42:$U$42<>""))+SUMIFS($E$521:$E$560,$C$521:$C$560,$B31,$D$521:$D$560,"77W",$B$521:$B$560,">="&$O$4,$B$521:$B$560,"<="&$O$5) -> 0 | K31: =SUMPRODUCT($C$20:$I$20,--($O$43:$U$43<>""))+SUMIFS($E$521:$E$560,$C$521:$C$560,$B31,$D$521:$D$560,"778",$B$521:$B$560,">="&$O$4,$B$521:$B$560,"<="&$O$5) -> 0 | L31: =SUMPRODUCT($C$20:$I$20,--($O$44:$U$44<>""))+SUMIFS($E$521:$E$560,$C$521:$C$560,$B31,$D$521:$D$560,"A320",$B$521:$B$560,">="&$O$4,$B$521:$B$560,"<="&$O$5) -> 13 | N31: BKKRUN - 778 | O31: =IFERROR(INDEX($D$49:$J$513,($O$7-1)*39+8,1)&"","") | P31: =IFERROR(INDEX($D$49:$J$513,($O$7-1)*39+8,2)&"","") | Q31: =IFERROR(INDEX($D$49:$J$513,($O$7-1)*39+8,3)&"","") -> x | R31: =IFERROR(INDEX($D$49:$J$513,($O$7-1)*39+8,4)&"","") | S31: =IFERROR(INDEX($D$49:$J$513,($O$7-1)*39+8,5)&"","") | T31: =IFERROR(INDEX($D$49:$J$513,($O$7-1)*39+8,6)&"","") -> x | U31: =IFERROR(INDEX($D$49:$J$513,($O$7-1)*39+8,7)&"","")
B32: =$Z$11 -> JNBRUN | C32: =IF(E32=0,"-",SUBSTITUTE(TRIM(IF(SUMPRODUCT(--($O$45:$U$45<>""))>0,"77W("&SUMPRODUCT(--($O$45:$U$45<>""))&") ","")&IF(SUMPRODUCT(--($O$46:$U$46<>""))>0,"778("&SUMPRODUCT(--($O$46:$U$46<>""))&") ","")&IF(SUMPRODUCT(--($O$47:$U$47<>""))>0,"A320("&SUMPRODUCT(--($O$47:$U$47<>""))&") ",""))," ",", ")) -> 778(2) | D32: =IF(E32=0,"aucune operation",SUBSTITUTE(TRIM(IF(SUMPRODUCT(--($O$45:$O$47<>""))>0,"J1 ","")&IF(SUMPRODUCT(--($P$45:$P$47<>""))>0,"J2 ","")&IF(SUMPRODUCT(--($Q$45:$Q$47<>""))>0,"J3 ","")&IF(SUMPRODUCT(--($R$45:$R$47<>""))>0,"J4 ","")&IF(SUMPRODUCT(--($S$45:$S$47<>""))>0,"J5 ","")&IF(SUMPRODUCT(--($T$45:$T$47<>""))>0,"J6 ","")&IF(SUMPRODUCT(--($U$45:$U$47<>""))>0,"J7 ",""))," ",", ")) -> J1, J5 | E32: =SUMPRODUCT(--($O$45:$U$47<>"")) -> 2 | F32: =$C$21 -> 5 | G32: =H32+I32 -> 9 | H32: =SUMPRODUCT($C$20:$I$20,--($O$45:$U$45<>""))+SUMPRODUCT($C$20:$I$20,--($O$46:$U$46<>""))+SUMPRODUCT($C$20:$I$20,--($O$47:$U$47<>"")) -> 9 | I32: =SUMIFS($E$521:$E$560,$C$521:$C$560,$B32,$B$521:$B$560,">="&$O$4,$B$521:$B$560,"<="&$O$5) -> 0 | J32: =SUMPRODUCT($C$20:$I$20,--($O$45:$U$45<>""))+SUMIFS($E$521:$E$560,$C$521:$C$560,$B32,$D$521:$D$560,"77W",$B$521:$B$560,">="&$O$4,$B$521:$B$560,"<="&$O$5) -> 0 | K32: =SUMPRODUCT($C$20:$I$20,--($O$46:$U$46<>""))+SUMIFS($E$521:$E$560,$C$521:$C$560,$B32,$D$521:$D$560,"778",$B$521:$B$560,">="&$O$4,$B$521:$B$560,"<="&$O$5) -> 9 | L32: =SUMPRODUCT($C$20:$I$20,--($O$47:$U$47<>""))+SUMIFS($E$521:$E$560,$C$521:$C$560,$B32,$D$521:$D$560,"A320",$B$521:$B$560,">="&$O$4,$B$521:$B$560,"<="&$O$5) -> 0 | N32: BKKRUN - A320 | O32: =IFERROR(INDEX($D$49:$J$513,($O$7-1)*39+9,1)&"","") | P32: =IFERROR(INDEX($D$49:$J$513,($O$7-1)*39+9,2)&"","") | Q32: =IFERROR(INDEX($D$49:$J$513,($O$7-1)*39+9,3)&"","") | R32: =IFERROR(INDEX($D$49:$J$513,($O$7-1)*39+9,4)&"","") | S32: =IFERROR(INDEX($D$49:$J$513,($O$7-1)*39+9,5)&"","") | T32: =IFERROR(INDEX($D$49:$J$513,($O$7-1)*39+9,6)&"","") | U32: =IFERROR(INDEX($D$49:$J$513,($O$7-1)*39+9,7)&"","")
B33: =$Z$12 -> CPTRUN | C33: =IF(E33=0,"-",SUBSTITUTE(TRIM(IF(SUMPRODUCT(--($O$48:$U$48<>""))>0,"77W("&SUMPRODUCT(--($O$48:$U$48<>""))&") ","")&IF(SUMPRODUCT(--($O$49:$U$49<>""))>0,"778("&SUMPRODUCT(--($O$49:$U$49<>""))&") ","")&IF(SUMPRODUCT(--($O$50:$U$50<>""))>0,"A320("&SUMPRODUCT(--($O$50:$U$50<>""))&") ",""))," ",", ")) -> 778(1) | D33: =IF(E33=0,"aucune operation",SUBSTITUTE(TRIM(IF(SUMPRODUCT(--($O$48:$O$50<>""))>0,"J1 ","")&IF(SUMPRODUCT(--($P$48:$P$50<>""))>0,"J2 ","")&IF(SUMPRODUCT(--($Q$48:$Q$50<>""))>0,"J3 ","")&IF(SUMPRODUCT(--($R$48:$R$50<>""))>0,"J4 ","")&IF(SUMPRODUCT(--($S$48:$S$50<>""))>0,"J5 ","")&IF(SUMPRODUCT(--($T$48:$T$50<>""))>0,"J6 ","")&IF(SUMPRODUCT(--($U$48:$U$50<>""))>0,"J7 ",""))," ",", ")) -> J4 | E33: =SUMPRODUCT(--($O$48:$U$50<>"")) -> 1 | F33: =$C$21 -> 5 | G33: =H33+I33 -> 5 | H33: =SUMPRODUCT($C$20:$I$20,--($O$48:$U$48<>""))+SUMPRODUCT($C$20:$I$20,--($O$49:$U$49<>""))+SUMPRODUCT($C$20:$I$20,--($O$50:$U$50<>"")) -> 5 | I33: =SUMIFS($E$521:$E$560,$C$521:$C$560,$B33,$B$521:$B$560,">="&$O$4,$B$521:$B$560,"<="&$O$5) -> 0 | J33: =SUMPRODUCT($C$20:$I$20,--($O$48:$U$48<>""))+SUMIFS($E$521:$E$560,$C$521:$C$560,$B33,$D$521:$D$560,"77W",$B$521:$B$560,">="&$O$4,$B$521:$B$560,"<="&$O$5) -> 0 | K33: =SUMPRODUCT($C$20:$I$20,--($O$49:$U$49<>""))+SUMIFS($E$521:$E$560,$C$521:$C$560,$B33,$D$521:$D$560,"778",$B$521:$B$560,">="&$O$4,$B$521:$B$560,"<="&$O$5) -> 5 | L33: =SUMPRODUCT($C$20:$I$20,--($O$50:$U$50<>""))+SUMIFS($E$521:$E$560,$C$521:$C$560,$B33,$D$521:$D$560,"A320",$B$521:$B$560,">="&$O$4,$B$521:$B$560,"<="&$O$5) -> 0 | N33: DZARUN - 77W | O33: =IFERROR(INDEX($D$49:$J$513,($O$7-1)*39+10,1)&"","") | P33: =IFERROR(INDEX($D$49:$J$513,($O$7-1)*39+10,2)&"","") | Q33: =IFERROR(INDEX($D$49:$J$513,($O$7-1)*39+10,3)&"","") | R33: =IFERROR(INDEX($D$49:$J$513,($O$7-1)*39+10,4)&"","") | S33: =IFERROR(INDEX($D$49:$J$513,($O$7-1)*39+10,5)&"","") | T33: =IFERROR(INDEX($D$49:$J$513,($O$7-1)*39+10,6)&"","") | U33: =IFERROR(INDEX($D$49:$J$513,($O$7-1)*39+10,7)&"","")
B34: =$Z$13 -> DIERUN | C34: =IF(E34=0,"-",SUBSTITUTE(TRIM(IF(SUMPRODUCT(--($O$51:$U$51<>""))>0,"77W("&SUMPRODUCT(--($O$51:$U$51<>""))&") ","")&IF(SUMPRODUCT(--($O$52:$U$52<>""))>0,"778("&SUMPRODUCT(--($O$52:$U$52<>""))&") ","")&IF(SUMPRODUCT(--($O$53:$U$53<>""))>0,"A320("&SUMPRODUCT(--($O$53:$U$53<>""))&") ",""))," ",", ")) -> A320(2) | D34: =IF(E34=0,"aucune operation",SUBSTITUTE(TRIM(IF(SUMPRODUCT(--($O$51:$O$53<>""))>0,"J1 ","")&IF(SUMPRODUCT(--($P$51:$P$53<>""))>0,"J2 ","")&IF(SUMPRODUCT(--($Q$51:$Q$53<>""))>0,"J3 ","")&IF(SUMPRODUCT(--($R$51:$R$53<>""))>0,"J4 ","")&IF(SUMPRODUCT(--($S$51:$S$53<>""))>0,"J5 ","")&IF(SUMPRODUCT(--($T$51:$T$53<>""))>0,"J6 ","")&IF(SUMPRODUCT(--($U$51:$U$53<>""))>0,"J7 ",""))," ",", ")) -> J2, J6 | E34: =SUMPRODUCT(--($O$51:$U$53<>"")) -> 2 | F34: =$C$21 -> 5 | G34: =H34+I34 -> 8 | H34: =SUMPRODUCT($C$20:$I$20,--($O$51:$U$51<>""))+SUMPRODUCT($C$20:$I$20,--($O$52:$U$52<>""))+SUMPRODUCT($C$20:$I$20,--($O$53:$U$53<>"")) -> 8 | I34: =SUMIFS($E$521:$E$560,$C$521:$C$560,$B34,$B$521:$B$560,">="&$O$4,$B$521:$B$560,"<="&$O$5) -> 0 | J34: =SUMPRODUCT($C$20:$I$20,--($O$51:$U$51<>""))+SUMIFS($E$521:$E$560,$C$521:$C$560,$B34,$D$521:$D$560,"77W",$B$521:$B$560,">="&$O$4,$B$521:$B$560,"<="&$O$5) -> 0 | K34: =SUMPRODUCT($C$20:$I$20,--($O$52:$U$52<>""))+SUMIFS($E$521:$E$560,$C$521:$C$560,$B34,$D$521:$D$560,"778",$B$521:$B$560,">="&$O$4,$B$521:$B$560,"<="&$O$5) -> 0 | L34: =SUMPRODUCT($C$20:$I$20,--($O$53:$U$53<>""))+SUMIFS($E$521:$E$560,$C$521:$C$560,$B34,$D$521:$D$560,"A320",$B$521:$B$560,">="&$O$4,$B$521:$B$560,"<="&$O$5) -> 8 | N34: DZARUN - 778 | O34: =IFERROR(INDEX($D$49:$J$513,($O$7-1)*39+11,1)&"","") | P34: =IFERROR(INDEX($D$49:$J$513,($O$7-1)*39+11,2)&"","") | Q34: =IFERROR(INDEX($D$49:$J$513,($O$7-1)*39+11,3)&"","") -> x | R34: =IFERROR(INDEX($D$49:$J$513,($O$7-1)*39+11,4)&"","") | S34: =IFERROR(INDEX($D$49:$J$513,($O$7-1)*39+11,5)&"","") | T34: =IFERROR(INDEX($D$49:$J$513,($O$7-1)*39+11,6)&"","") | U34: =IFERROR(INDEX($D$49:$J$513,($O$7-1)*39+11,7)&"","")
B35: =$Z$14 -> RRGRUN | C35: =IF(E35=0,"-",SUBSTITUTE(TRIM(IF(SUMPRODUCT(--($O$54:$U$54<>""))>0,"77W("&SUMPRODUCT(--($O$54:$U$54<>""))&") ","")&IF(SUMPRODUCT(--($O$55:$U$55<>""))>0,"778("&SUMPRODUCT(--($O$55:$U$55<>""))&") ","")&IF(SUMPRODUCT(--($O$56:$U$56<>""))>0,"A320("&SUMPRODUCT(--($O$56:$U$56<>""))&") ",""))," ",", ")) -> A320(6) | D35: =IF(E35=0,"aucune operation",SUBSTITUTE(TRIM(IF(SUMPRODUCT(--($O$54:$O$56<>""))>0,"J1 ","")&IF(SUMPRODUCT(--($P$54:$P$56<>""))>0,"J2 ","")&IF(SUMPRODUCT(--($Q$54:$Q$56<>""))>0,"J3 ","")&IF(SUMPRODUCT(--($R$54:$R$56<>""))>0,"J4 ","")&IF(SUMPRODUCT(--($S$54:$S$56<>""))>0,"J5 ","")&IF(SUMPRODUCT(--($T$54:$T$56<>""))>0,"J6 ","")&IF(SUMPRODUCT(--($U$54:$U$56<>""))>0,"J7 ",""))," ",", ")) -> J1, J2, J3, J4, J5, J6 | E35: =SUMPRODUCT(--($O$54:$U$56<>"")) -> 6 | F35: =$C$21 -> 5 | G35: =H35+I35 -> 26 | H35: =SUMPRODUCT($C$20:$I$20,--($O$54:$U$54<>""))+SUMPRODUCT($C$20:$I$20,--($O$55:$U$55<>""))+SUMPRODUCT($C$20:$I$20,--($O$56:$U$56<>"")) -> 26 | I35: =SUMIFS($E$521:$E$560,$C$521:$C$560,$B35,$B$521:$B$560,">="&$O$4,$B$521:$B$560,"<="&$O$5) -> 0 | J35: =SUMPRODUCT($C$20:$I$20,--($O$54:$U$54<>""))+SUMIFS($E$521:$E$560,$C$521:$C$560,$B35,$D$521:$D$560,"77W",$B$521:$B$560,">="&$O$4,$B$521:$B$560,"<="&$O$5) -> 0 | K35: =SUMPRODUCT($C$20:$I$20,--($O$55:$U$55<>""))+SUMIFS($E$521:$E$560,$C$521:$C$560,$B35,$D$521:$D$560,"778",$B$521:$B$560,">="&$O$4,$B$521:$B$560,"<="&$O$5) -> 0 | L35: =SUMPRODUCT($C$20:$I$20,--($O$56:$U$56<>""))+SUMIFS($E$521:$E$560,$C$521:$C$560,$B35,$D$521:$D$560,"A320",$B$521:$B$560,">="&$O$4,$B$521:$B$560,"<="&$O$5) -> 26 | N35: DZARUN - A320 | O35: =IFERROR(INDEX($D$49:$J$513,($O$7-1)*39+12,1)&"","") -> x | P35: =IFERROR(INDEX($D$49:$J$513,($O$7-1)*39+12,2)&"","") -> x | Q35: =IFERROR(INDEX($D$49:$J$513,($O$7-1)*39+12,3)&"","") -> x | R35: =IFERROR(INDEX($D$49:$J$513,($O$7-1)*39+12,4)&"","") -> x | S35: =IFERROR(INDEX($D$49:$J$513,($O$7-1)*39+12,5)&"","") -> x | T35: =IFERROR(INDEX($D$49:$J$513,($O$7-1)*39+12,6)&"","") | U35: =IFERROR(INDEX($D$49:$J$513,($O$7-1)*39+12,7)&"","")
B36: =$Z$15 -> TMMRUN | C36: =IF(E36=0,"-",SUBSTITUTE(TRIM(IF(SUMPRODUCT(--($O$57:$U$57<>""))>0,"77W("&SUMPRODUCT(--($O$57:$U$57<>""))&") ","")&IF(SUMPRODUCT(--($O$58:$U$58<>""))>0,"778("&SUMPRODUCT(--($O$58:$U$58<>""))&") ","")&IF(SUMPRODUCT(--($O$59:$U$59<>""))>0,"A320("&SUMPRODUCT(--($O$59:$U$59<>""))&") ",""))," ",", ")) -> A320(2) | D36: =IF(E36=0,"aucune operation",SUBSTITUTE(TRIM(IF(SUMPRODUCT(--($O$57:$O$59<>""))>0,"J1 ","")&IF(SUMPRODUCT(--($P$57:$P$59<>""))>0,"J2 ","")&IF(SUMPRODUCT(--($Q$57:$Q$59<>""))>0,"J3 ","")&IF(SUMPRODUCT(--($R$57:$R$59<>""))>0,"J4 ","")&IF(SUMPRODUCT(--($S$57:$S$59<>""))>0,"J5 ","")&IF(SUMPRODUCT(--($T$57:$T$59<>""))>0,"J6 ","")&IF(SUMPRODUCT(--($U$57:$U$59<>""))>0,"J7 ",""))," ",", ")) -> J3, J7 | E36: =SUMPRODUCT(--($O$57:$U$59<>"")) -> 2 | F36: =$C$21 -> 5 | G36: =H36+I36 -> 8 | H36: =SUMPRODUCT($C$20:$I$20,--($O$57:$U$57<>""))+SUMPRODUCT($C$20:$I$20,--($O$58:$U$58<>""))+SUMPRODUCT($C$20:$I$20,--($O$59:$U$59<>"")) -> 8 | I36: =SUMIFS($E$521:$E$560,$C$521:$C$560,$B36,$B$521:$B$560,">="&$O$4,$B$521:$B$560,"<="&$O$5) -> 0 | J36: =SUMPRODUCT($C$20:$I$20,--($O$57:$U$57<>""))+SUMIFS($E$521:$E$560,$C$521:$C$560,$B36,$D$521:$D$560,"77W",$B$521:$B$560,">="&$O$4,$B$521:$B$560,"<="&$O$5) -> 0 | K36: =SUMPRODUCT($C$20:$I$20,--($O$58:$U$58<>""))+SUMIFS($E$521:$E$560,$C$521:$C$560,$B36,$D$521:$D$560,"778",$B$521:$B$560,">="&$O$4,$B$521:$B$560,"<="&$O$5) -> 0 | L36: =SUMPRODUCT($C$20:$I$20,--($O$59:$U$59<>""))+SUMIFS($E$521:$E$560,$C$521:$C$560,$B36,$D$521:$D$560,"A320",$B$521:$B$560,">="&$O$4,$B$521:$B$560,"<="&$O$5) -> 8 | N36: MRURUN - 77W | O36: =IFERROR(INDEX($D$49:$J$513,($O$7-1)*39+13,1)&"","") | P36: =IFERROR(INDEX($D$49:$J$513,($O$7-1)*39+13,2)&"","") | Q36: =IFERROR(INDEX($D$49:$J$513,($O$7-1)*39+13,3)&"","") | R36: =IFERROR(INDEX($D$49:$J$513,($O$7-1)*39+13,4)&"","") | S36: =IFERROR(INDEX($D$49:$J$513,($O$7-1)*39+13,5)&"","") | T36: =IFERROR(INDEX($D$49:$J$513,($O$7-1)*39+13,6)&"","") | U36: =IFERROR(INDEX($D$49:$J$513,($O$7-1)*39+13,7)&"","")
B37: TOTAL GENERAL | E37: =SUM(E25:E36) -> 44 | F37: =$C$21 -> 5 | G37: =SUM(G25:G36) -> 193 | H37: =SUM(H25:H36) -> 189 | I37: =SUM(I25:I36) -> 4 | J37: =SUM(J25:J36) -> 34 | K37: =SUM(K25:K36) -> 46 | L37: =SUM(L25:L36) -> 113 | N37: MRURUN - 778 | O37: =IFERROR(INDEX($D$49:$J$513,($O$7-1)*39+14,1)&"","") | P37: =IFERROR(INDEX($D$49:$J$513,($O$7-1)*39+14,2)&"","") | Q37: =IFERROR(INDEX($D$49:$J$513,($O$7-1)*39+14,3)&"","") | R37: =IFERROR(INDEX($D$49:$J$513,($O$7-1)*39+14,4)&"","") | S37: =IFERROR(INDEX($D$49:$J$513,($O$7-1)*39+14,5)&"","") | T37: =IFERROR(INDEX($D$49:$J$513,($O$7-1)*39+14,6)&"","") | U37: =IFERROR(INDEX($D$49:$J$513,($O$7-1)*39+14,7)&"","")
B38: Methode : le recapitulatif lit le tableau de saisie du mois filtre. Pour chaque jour coche, le nombre d'occurrences de ce jour dans le mois est compte a partir des dates reelles de la grille (ligne "Occurrences du jour dans le mois", semaines partielles incluses), chaque type avion etant compte separement. Total rotations du mois = programme du mois + vols additionnels dates. Une case cochee = 1 rotation ; pour deux rotations du meme type le meme jour, utiliser la table des vols additionnels. | N38: MRURUN - A320 | O38: =IFERROR(INDEX($D$49:$J$513,($O$7-1)*39+15,1)&"","") -> x | P38: =IFERROR(INDEX($D$49:$J$513,($O$7-1)*39+15,2)&"","") | Q38: =IFERROR(INDEX($D$49:$J$513,($O$7-1)*39+15,3)&"","") -> x | R38: =IFERROR(INDEX($D$49:$J$513,($O$7-1)*39+15,4)&"","") | S38: =IFERROR(INDEX($D$49:$J$513,($O$7-1)*39+15,5)&"","") -> x | T38: =IFERROR(INDEX($D$49:$J$513,($O$7-1)*39+15,6)&"","") | U38: =IFERROR(INDEX($D$49:$J$513,($O$7-1)*39+15,7)&"","") -> x
N39: NOSRUN - 77W | O39: =IFERROR(INDEX($D$49:$J$513,($O$7-1)*39+16,1)&"","") | P39: =IFERROR(INDEX($D$49:$J$513,($O$7-1)*39+16,2)&"","") | Q39: =IFERROR(INDEX($D$49:$J$513,($O$7-1)*39+16,3)&"","") | R39: =IFERROR(INDEX($D$49:$J$513,($O$7-1)*39+16,4)&"","") | S39: =IFERROR(INDEX($D$49:$J$513,($O$7-1)*39+16,5)&"","") | T39: =IFERROR(INDEX($D$49:$J$513,($O$7-1)*39+16,6)&"","") | U39: =IFERROR(INDEX($D$49:$J$513,($O$7-1)*39+16,7)&"","")
N40: NOSRUN - 778 | O40: =IFERROR(INDEX($D$49:$J$513,($O$7-1)*39+17,1)&"","") | P40: =IFERROR(INDEX($D$49:$J$513,($O$7-1)*39+17,2)&"","") | Q40: =IFERROR(INDEX($D$49:$J$513,($O$7-1)*39+17,3)&"","") | R40: =IFERROR(INDEX($D$49:$J$513,($O$7-1)*39+17,4)&"","") | S40: =IFERROR(INDEX($D$49:$J$513,($O$7-1)*39+17,5)&"","") | T40: =IFERROR(INDEX($D$49:$J$513,($O$7-1)*39+17,6)&"","") | U40: =IFERROR(INDEX($D$49:$J$513,($O$7-1)*39+17,7)&"","")
...

Sheet Analyse capacite
B1: ANALYSE DE CAPACITE - SIEGES OFFERTS (avril 2027 / mars 2028)
B2: Cette feuille interprete automatiquement la feuille "Programme de vols" (les 12 tableaux mensuels et les vols additionnels) en la croisant avec les capacites ci-dessous. Aucune saisie ici, hormis les sieges par type avion. Toute modification du programme met a jour cette feuille.
B4: HYPOTHESES DE CAPACITE (sieges par rotation)
B5: Type avion | C5: Sieges par rotation | D5: Remarque
B6: 77W | C6: 438 | D6: Valeur fournie (77W = 777-300ER).
B7: 778 | C7: 262 | D7: Valeur fournie pour le 787 (Dreamliner) ; code type 778 de la feuille 1.
B8: A320 | C8: 174 | D8: Valeur fournie (A320).
B11: SYNTHESE ANNUELLE PAR ROUTE
B12: Route | C12: Rotations sur l'annee | D12: Sieges offerts sur l'annee | E12: Sieges / rotation | F12: Part du reseau (sieges)
B13: CDGRUN | C13: =SUM(C$46:C$57) -> 542 | D13: =SUM(C$29:C$40) -> 202284 | E13: =IFERROR(D13/C13,"-") -> 373.21771 | F13: =IFERROR(D13/$D$25,0) -> 0.35822006
B14: CDGDZA | C14: =SUM(D$46:D$57) -> 157 | D14: =SUM(D$29:D$40) -> 50286 | E14: =IFERROR(D14/C14,"-") -> 320.29299 | F14: =IFERROR(D14/$D$25,0) -> 0.089050314
B15: BKKRUN | C15: =SUM(E$46:E$57) -> 104 | D15: =SUM(E$29:E$40) -> 27248 | E15: =IFERROR(D15/C15,"-") -> 262 | F15: =IFERROR(D15/$D$25,0) -> 0.048252853
B16: DZARUN | C16: =SUM(F$46:F$57) -> 314 | D16: =SUM(F$29:F$40) -> 59212 | E16: =IFERROR(D16/C16,"-") -> 188.57325 | F16: =IFERROR(D16/$D$25,0) -> 0.10485716
B17: MRURUN | C17: =SUM(G$46:G$57) -> 209 | D17: =SUM(G$29:G$40) -> 36366 | E17: =IFERROR(D17/C17,"-") -> 174 | F17: =IFERROR(D17/$D$25,0) -> 0.064399708
B18: NOSRUN | C18: =SUM(H$46:H$57) -> 171 | D18: =SUM(H$29:H$40) -> 29754 | E18: =IFERROR(D18/C18,"-") -> 174 | F18: =IFERROR(D18/$D$25,0) -> 0.05269067
